Workbook

Sheet 員工名冊
A1: 日三牙醫體系 員工名冊(2026/09/16 製)
A2: 人數 | B2: 總人數 | C2: =COUNTA($B$4:$B$37) -> 34 | D2: 醫師 | E2: =COUNTIF($D$4:$D$37,"醫師") -> 27 | F2: 醫護長 | G2: =COUNTIF($D$4:$D$37,"醫護長") -> 4 | H2: 管理部 | I2: =COUNTIF($D$4:$D$37,"管理部") -> 3 | J2: 院長 | K2: =COUNTIF($E$4:$E$37,"院長") -> 5
A3: 序號 | B3: 員工編號 | C3: 姓名 | D3: 英文名 | E3: 職類 | F3: 職務 | G3: 專科 | H3: 主要院所 | I3: 服務院所 | J3: 跨院數 | K3: 到職日 | L3: 備註
A4: 1 | B4: D001 | C4: 林智俊 | D4: JASON LIN | E4: 醫師 | F4: 院長 | G4: 牙周植牙專科 | H4: 晶悅 | I4: 晶悅 · 晶睿 · 晶匯 · 晶曜 | J4: =IF($I4="","",LEN($I4)-LEN(SUBSTITUTE($I4,"·",""))+1) -> 4
A5: 2 | B5: D002 | C5: 劉立德 | D5: LEADER LIU | E5: 醫師 | F5: 院長 | G5: 植牙專科 家庭牙醫專科 | H5: 晶曜 | I5: 晶睿 · 晶曜 | J5: =IF($I5="","",LEN($I5)-LEN(SUBSTITUTE($I5,"·",""))+1) -> 2
A6: 3 | B6: D003 | C6: 王泳泉 | D6: RYAN WANG | E6: 醫師 | G6: 矯正專科 | H6: 晶悅 | I6: 晶悅 · 晶睿 | J6: =IF($I6="","",LEN($I6)-LEN(SUBSTITUTE($I6,"·",""))+1) -> 2
A7: 4 | B7: D004 | C7: 劉玠旻 | D7: CHIEH-MIN LIU | E7: 醫師 | G7: 兒童專科 | H7: 晶悅 | I7: 晶悅 · 晶睿 · 晶曜 | J7: =IF($I7="","",LEN($I7)-LEN(SUBSTITUTE($I7,"·",""))+1) -> 3
A8: 5 | B8: D005 | C8: 陳志僑 | D8: CHIH-CHIAO CHEN | E8: 醫師 | G8: 口外專科 | H8: 晶悅 | I8: 晶悅 · 晶睿 | J8: =IF($I8="","",LEN($I8)-LEN(SUBSTITUTE($I8,"·",""))+1) -> 2
A9: 6 | B9: D006 | C9: 黃榆鈞 | D9: YU-CHUN HUANG | E9: 醫師 | G9: 矯正專科 | H9: 寶貝牙 | I9: 晶悅 · 寶貝牙 | J9: =IF($I9="","",LEN($I9)-LEN(SUBSTITUTE($I9,"·",""))+1) -> 2
A10: 7 | B10: D007 | C10: 温翊君 | D10: YI-CHUN WEN | E10: 醫師 | G10: 根管治療專科 | H10: 晶悅 | I10: 晶悅 | J10: =IF($I10="","",LEN($I10)-LEN(SUBSTITUTE($I10,"·",""))+1) -> 1
A11: 8 | B11: D008 | C11: 林紫亭 | D11: TZU-TING LIN | E11: 醫師 | H11: 晶悅 | I11: 晶悅 | J11: =IF($I11="","",LEN($I11)-LEN(SUBSTITUTE($I11,"·",""))+1) -> 1
A12: 9 | B12: D009 | C12: 陳昺元 | D12: PING-YUAN CHEN | E12: 醫師 | F12: 院長 | G12: 美學植牙專科 | H12: 晶匯 | I12: 晶悅 · 晶匯 · 寶貝牙 | J12: =IF($I12="","",LEN($I12)-LEN(SUBSTITUTE($I12,"·",""))+1) -> 3
A13: 10 | B13: D010 | C13: 蔡季軒 | D13: CHI-HSUAN TSAI | E13: 醫師 | H13: 晶悅 | I13: 晶悅 | J13: =IF($I13="","",LEN($I13)-LEN(SUBSTITUTE($I13,"·",""))+1) -> 1
A14: 11 | B14: D011 | C14: 温健成 | D14: JIAN-CHENG WEN | E14: 醫師 | F14: 院長 | H14: 晶睿 | I14: 晶睿 · 晶匯 | J14: =IF($I14="","",LEN($I14)-LEN(SUBSTITUTE($I14,"·",""))+1) -> 2
A15: 12 | B15: D012 | C15: 陳立軒 | D15: LI-HSUAN CHEN | E15: 醫師 | H15: 晶曜 | I15: 晶睿 · 晶匯 · 晶曜 | J15: =IF($I15="","",LEN($I15)-LEN(SUBSTITUTE($I15,"·",""))+1) -> 3
A16: 13 | B16: D013 | C16: 朱柏非 | D16: PO-FEI CHU | E16: 醫師 | H16: 晶悅 | I16: 晶悅 · 晶匯 · 寶貝牙 | J16: =IF($I16="","",LEN($I16)-LEN(SUBSTITUTE($I16,"·",""))+1) -> 3
A17: 14 | B17: D014 | C17: 鄭漢賢 | D17: HON-YIN CHENG | E17: 醫師 | H17: 晶悅 | I17: 晶悅 · 晶匯 | J17: =IF($I17="","",LEN($I17)-LEN(SUBSTITUTE($I17,"·",""))+1) -> 2
A18: 15 | B18: D015 | C18: 徐平 | D18: PING HSU | E18: 醫師 | H18: 晶曜 | I18: 晶悅 · 晶曜 | J18: =IF($I18="","",LEN($I18)-LEN(SUBSTITUTE($I18,"·",""))+1) -> 2
A19: 16 | B19: D016 | C19: 賴敏傑 | D19: MIN-CHIEH LAI | E19: 醫師 | H19: 晶睿 | I19: 晶睿 | J19: =IF($I19="","",LEN($I19)-LEN(SUBSTITUTE($I19,"·",""))+1) -> 1
A20: 17 | B20: D017 | C20: 吳柏賢 | D20: BO-XIAN WU | E20: 醫師 | H20: 晶曜 | I20: 晶睿 · 晶曜 | J20: =IF($I20="","",LEN($I20)-LEN(SUBSTITUTE($I20,"·",""))+1) -> 2
A21: 18 | B21: D018 | C21: 許博諺 | D21: PO-YEN HSU | E21: 醫師 | H21: 晶曜 | I21: 晶睿 · 晶曜 | J21: =IF($I21="","",LEN($I21)-LEN(SUBSTITUTE($I21,"·",""))+1) -> 2
A22: 19 | B22: D019 | C22: 翁崎紘 | D22: CHI-HONG WENG | E22: 醫師 | H22: 晶悅 | I22: 晶悅 | J22: =IF($I22="","",LEN($I22)-LEN(SUBSTITUTE($I22,"·",""))+1) -> 1
A23: 20 | B23: D020 | C23: 余柏萱 | D23: PO-HSUAN YU | E23: 醫師 | H23: 晶睿 | I23: 晶睿 · 寶貝牙 | J23: =IF($I23="","",LEN($I23)-LEN(SUBSTITUTE($I23,"·",""))+1) -> 2
A24: 21 | B24: D021 | C24: 鄭博文 | D24: PO-WEN CHENG | E24: 醫師 | H24: 晶悅 | I24: 晶悅 | J24: =IF($I24="","",LEN($I24)-LEN(SUBSTITUTE($I24,"·",""))+1) -> 1
A25: 22 | B25: D022 | C25: 黃育亭 | D25: YU-TING HUANG | E25: 醫師 | F25: 院長 | G25: 兒童 | H25: 寶貝牙 | I25: 寶貝牙 | J25: =IF($I25="","",LEN($I25)-LEN(SUBSTITUTE($I25,"·",""))+1) -> 1
A26: 23 | B26: D023 | C26: 黃婷愉 | D26: TING-YU HUANG | E26: 醫師 | G26: 口外 | H26: 寶貝牙 | I26: 寶貝牙 | J26: =IF($I26="","",LEN($I26)-LEN(SUBSTITUTE($I26,"·",""))+1) -> 1
A27: 24 | B27: D024 | C27: 林紓安 | D27: SHU-AN LIN | E27: 醫師 | G27: 兒童 | H27: 寶貝牙 | I27: 晶匯 · 寶貝牙 | J27: =IF($I27="","",LEN($I27)-LEN(SUBSTITUTE($I27,"·",""))+1) -> 2
A28: 25 | B28: D025 | C28: 陳爵安 | E28: 醫師 | H28: 晶睿 | I28: 晶睿 | J28: =IF($I28="","",LEN($I28)-LEN(SUBSTITUTE($I28,"·",""))+1) -> 1 | L28: 官網醫療團隊頁未收錄,資料待補
A29: 26 | B29: D026 | C29: 吳冠廷 | E29: 醫師 | H29: 晶匯 | I29: 晶匯 | J29: =IF($I29="","",LEN($I29)-LEN(SUBSTITUTE($I29,"·",""))+1) -> 1 | L29: 官網醫療團隊頁未收錄,資料待補
A30: 27 | B30: D027 | C30: 楊孟庭 | E30: 醫師 | H30: 晶匯 | I30: 晶匯 | J30: =IF($I30="","",LEN($I30)-LEN(SUBSTITUTE($I30,"·",""))+1) -> 1 | L30: 官網醫療團隊頁未收錄,資料待補
A31: 28 | B31: N001 | C31: ivy | E31: 醫護長 | H31: 晶悅 | I31: 晶悅 | J31: =IF($I31="","",LEN($I31)-LEN(SUBSTITUTE($I31,"·",""))+1) -> 1
A32: 29 | B32: N002 | C32: 文君 | E32: 醫護長 | H32: 晶睿 | I32: 晶睿 · 晶曜 | J32: =IF($I32="","",LEN($I32)-LEN(SUBSTITUTE($I32,"·",""))+1) -> 2 | L32: 兼管晶睿與晶曜
A33: 30 | B33: N003 | C33: 小玲 | E33: 醫護長 | H33: 晶匯 | I33: 晶匯 | J33: =IF($I33="","",LEN($I33)-LEN(SUBSTITUTE($I33,"·",""))+1) -> 1
A34: 31 | B34: N004 | C34: 娜娜 | E34: 醫護長 | H34: 寶貝牙 | I34: 寶貝牙 | J34: =IF($I34="","",LEN($I34)-LEN(SUBSTITUTE($I34,"·",""))+1) -> 1
A35: 32 | B35: M001 | C35: 孟諭 | E35: 管理部 | H35: 晶匯 | I35: 晶匯 | J35: =IF($I35="","",LEN($I35)-LEN(SUBSTITUTE($I35,"·",""))+1) -> 1
A36: 33 | B36: M002 | C36: 怡雯 | E36: 管理部 | H36: 晶匯 | I36: 晶匯 | J36: =IF($I36="","",LEN($I36)-LEN(SUBSTITUTE($I36,"·",""))+1) -> 1
A37: 34 | B37: M003 | C37: 小華 | E37: 管理部 | H37: 晶匯 | I37: 晶匯 | J37: =IF($I37="","",LEN($I37)-LEN(SUBSTITUTE($I37,"·",""))+1) -> 1
A39: 【怎麼用】黃底的「到職日」是唯一要手填的欄位,請填真正的日期格式(例：2020/3/15),不要填成文字。填好之後特休年資才算得出來——目前 34 人全部空白。
A40: 【自動欄位】第 2 列的人數與「跨院數」是公式,加人或改「服務院所」會自己更新,不必手改。
A41: 【資料來源】醫師的姓名、英文名、專科、服務院所取自 gemray.tw 官網醫療團隊頁與五間院所門診表;醫護長與管理部由小編提供。
...

Sheet 院所對照
A1: 院所對照與人數
A2: 代碼 | B2: 簡稱 | C2: 全名 | D2: 院長 | E2: 電話 | F2: 地址 | G2: 醫師 | H2: 醫護長 | I2: 管理部 | J2: 合計
A3: 悅 | B3: 晶悅 | C3: 晶悅牙醫診所 | D3: 林智俊 | E3: 03-4257710 | F3: 320桃園市中壢區新生路251號 | G3: =SUMPRODUCT(ISNUMBER(SEARCH("晶悅",員工名冊!$I$4:$I$37))*(員工名冊!$D$4:$D$37="醫師")) -> 14 | H3: =SUMPRODUCT(ISNUMBER(SEARCH("晶悅",員工名冊!$I$4:$I$37))*(員工名冊!$D$4:$D$37="醫護長")) -> 1 | I3: =SUMPRODUCT(ISNUMBER(SEARCH("晶悅",員工名冊!$I$4:$I$37))*(員工名冊!$D$4:$D$37="管理部")) -> 0 | J3: =SUM(G3:I3) -> 15
A4: 睿 | B4: 晶睿 | C4: 晶睿牙醫診所 | D4: 温健成 | E4: 03-4522360 | F4: 桃園市中壢區福州二街502號 | G4: =SUMPRODUCT(ISNUMBER(SEARCH("晶睿",員工名冊!$I$4:$I$37))*(員工名冊!$D$4:$D$37="醫師")) -> 12 | H4: =SUMPRODUCT(ISNUMBER(SEARCH("晶睿",員工名冊!$I$4:$I$37))*(員工名冊!$D$4:$D$37="醫護長")) -> 1 | I4: =SUMPRODUCT(ISNUMBER(SEARCH("晶睿",員工名冊!$I$4:$I$37))*(員工名冊!$D$4:$D$37="管理部")) -> 0 | J4: =SUM(G4:I4) -> 13
A5: 匯 | B5: 晶匯 | C5: 晶匯牙醫診所 | D5: 陳昺元 | E5: 03-4550719 | F5: 桃園市中壢區成章一街172號 | G5: =SUMPRODUCT(ISNUMBER(SEARCH("晶匯",員工名冊!$I$4:$I$37))*(員工名冊!$D$4:$D$37="醫師")) -> 9 | H5: =SUMPRODUCT(ISNUMBER(SEARCH("晶匯",員工名冊!$I$4:$I$37))*(員工名冊!$D$4:$D$37="醫護長")) -> 1 | I5: =SUMPRODUCT(ISNUMBER(SEARCH("晶匯",員工名冊!$I$4:$I$37))*(員工名冊!$D$4:$D$37="管理部")) -> 3 | J5: =SUM(G5:I5) -> 13
A6: 曜 | B6: 晶曜 | C6: 晶曜牙醫診所 | D6: 劉立德 | E6: 03-3150666 | F6: 桃園市桃園區中正路1398-1號 | G6: =SUMPRODUCT(ISNUMBER(SEARCH("晶曜",員工名冊!$I$4:$I$37))*(員工名冊!$D$4:$D$37="醫師")) -> 7 | H6: =SUMPRODUCT(ISNUMBER(SEARCH("晶曜",員工名冊!$I$4:$I$37))*(員工名冊!$D$4:$D$37="醫護長")) -> 1 | I6: =SUMPRODUCT(ISNUMBER(SEARCH("晶曜",員工名冊!$I$4:$I$37))*(員工名冊!$D$4:$D$37="管理部")) -> 0 | J6: =SUM(G6:I6) -> 8
A7: 寶 | B7: 寶貝牙 | C7: 寶貝牙牙醫診所 | D7: 黃育亭 | E7: 03-2871688 | F7: 桃園市大園區新生路四段273號2樓 | G7: =SUMPRODUCT(ISNUMBER(SEARCH("寶貝牙",員工名冊!$I$4:$I$37))*(員工名冊!$D$4:$D$37="醫師")) -> 7 | H7: =SUMPRODUCT(ISNUMBER(SEARCH("寶貝牙",員工名冊!$I$4:$I$37))*(員工名冊!$D$4:$D$37="醫護長")) -> 1 | I7: =SUMPRODUCT(ISNUMBER(SEARCH("寶貝牙",員工名冊!$I$4:$I$37))*(員工名冊!$D$4:$D$37="管理部")) -> 0 | J7: =SUM(G7:I7) -> 8
A9: ※ 人數是用「服務院所」欄做包含比對算的,所以跨院醫師會在每一間都被計入一次,各院所合計會大於總人數 34。要看不重複人數請以「員工名冊」第 2 列為準。
A10: ※ 文君兼管晶睿與晶曜,是同一位、一個員工編號,兩間都會算到她。
