Workbook

Sheet 說明
B2: 日三牙醫體系 — 統一出勤表 使用說明
B4: 為什麼是一個檔 | C4: 體系 27 位醫師裡有 18 位跨院看診,林智俊院長一個人就跑四間。 若一間院所一個檔,排他一個月要開四個檔,而且沒有任何機制擋得住「同一個早診 同時被排在晶悅和晶睿」。所以全體系共用這一個檔。
B5: 醫師與助理為什麼分開排 | C5: 醫師的一天是「幾個診次」,助理的一天是「幾個小時」,兩者不能塞進同一種格子。 醫師 → 醫師班表:一人一列,橫向 31 天 × 早/午/晚,格內填院所代碼(悅睿匯曜寶)。 一格只容得下一間院所,衝堂在結構上就不可能發生。 助理與醫護長 → 助理班表:一人一列,橫向 31 天,格內填班別代碼(A/P/OFF/特…)。
B6: 九個分頁怎麼分工 | C6: ① 說明 ② 設定 — 總部維護,各院所勿動。 ③ 醫師週班表 — 官網門診表的固定週輪值,是排月班的母表。 ④ 醫師班表 ⑤ 醫師月結 — 本月實際診次,由週班表自動展開。 ⑥ 助理班表 — 各院所醫護長填自己院所那幾列。 ⑦ 打卡匯入 ⑧ 出勤紀錄 ⑨ 月結統計 — 助理與醫護長的法定出勤與月結。
B7: 週班表與月班表的關係 | C7: 門診表是固定的每週輪值,所以月班表不必一格一格填——「醫師班表」已經照 「醫師週班表」把整個月展開好了,直接改例外即可(請假就把該格改成假別代碼)。 ⚠ 改「設定」的本期年月只會更新日期與星期列,格子裡的班不會重排。換月份時 請告知重新產生,或自行把上個月的格子整段調整。
B8: 各院所診次時間不一樣 | C8: 晶悅/晶睿/晶匯/晶曜:早 09:00~11:30、午 14:00~16:30、晚 18:00~20:30。 寶貝牙:早 09:00~14:00、午 14:00~17:00、晚 17:30~21:00,且週一至週五早診休診。 五間院所週日全休、週六晚診全休。醫師班表的早/午/晚只是時段代號, 實際幾點到幾點依「設定」院所清單裡該院所的定義。開診時段表也在那裡。
B9: 每月作業流程 | C9: 上月底:總部排醫師班表 → 看底下五列「各院所每診次醫師數」有沒有 0 → 發給各院所。 各院所醫護長排助理班表 → 檢查人力檢核列 → 交回。 當月底:打卡機匯出檔貼進「打卡匯入」→ 到「出勤紀錄」處理異常 → 月結送人資。
B10: 醫師班表怎麼填 | C10: 每一天有三格:早診、午診、晚診。格內填院所代碼,空白代表該診次沒排班。 悅 = 晶悅 睿 = 晶睿 匯 = 晶匯 曜 = 晶曜 寶 = 寶貝牙 請假也是填在診次格裡(特/病/事/公/國/OFF/休),因為醫師請假常常只請半天。 所以醫師的月結一律以「診次」為單位,不是天數——請假 3 個診次就是請一天。 五種院所代碼各有底色,一位醫師整月在五間之間怎麼跑,橫著看一列就知道。
B11: 改班表哪裡會跟著變 | C11: 資料是這樣流的,兩邊改都會立刻反映到月結: 醫師週班表 →(公式)→ 醫師班表 →(公式)→ 醫師月結 ① 改「醫師週班表」= 改固定門診(某位醫師從此改成週三晚診)。 醫師班表整個月的對應格子會立刻跟著變,月結也立刻變。 ② 直接改「醫師班表」的格子 = 這個月的單次例外(某天請假、臨時調班)。 月結一樣立刻變。 ⚠ 但②有個副作用:你打字覆蓋的那一格,原本的公式就沒了, 從此不再跟著週班表走。那種格子會自動加上紅色外框提醒你。 要讓它恢復連動,從左右鄰近沒被改過的格子複製一格貼回來即可。 (旁邊的格子公式一樣,貼過來會自動對應到正確的日期與診次。)
B12: 醫師週班表的標記怎麼看 | C12: 週班表是母表,要表示「這一週在 A 院、下一週在 B 院」,所以比醫師班表多幾種寫法: 悅 每週固定在晶悅 悅(隔) 隔週在晶悅(單數週有、雙數週沒有) 悅/睿 兩間輪替——斜線前是單數週、斜線後是雙數週,全表共四組 寶(不定) 官網註明非每週固定,需向院所確認 悅(註) 有附加條件,寫在該列最右邊的附註欄 完整對照表在「設定」分頁的「二之二、醫師週班表的標記」。 醫師班表(月班表)不用這些標記,一格就是一個單純的代碼。
B13: 出勤紀錄怎麼看 | C13: 一人一天一列,自動把助理班表與打卡對起來,判定五種狀態: 正常、遲到、早退、未打卡、假日出勤。紅底 = 需處理;橘底 = 當天有加班。 用上方篩選鈕只看非「正常」的最快。沒有打卡機的院所,可把「實際上班/下班」 兩欄公式刪掉改成手填,其餘照算。
B14: 加班怎麼認定 | C14: 超過排班工時的分鐘數要跨過門檻(預設 30 分)才算加班,並無條件捨去到計算 單位(預設 30 分)。否則每天晚幾分鐘打卡都會被算成加班,一個月會憑空多出 好幾小時。遲到早退另有寬限(預設 5 分)。三個參數在「設定」的計算參數區。 這三個數字是勞資慣例、不是法規,上線前請人資確認,並讓同仁事先知道規則。
B15: 兩種下拉箭頭不一樣 | C15: 標題列上的箭頭是「篩選鈕」,用來隱藏或顯示列,不是拿來選資料的。 要選員工編號或班別代碼,請點「資料列」的格子——游標移上去右邊才會出現選單箭頭。 另外,助理班表、打卡匯入、出勤紀錄、月結統計這四個分頁在助理與醫護長名單匯入前 都是空的,篩選鈕點開只會看到「(空格)」,那是正常的,不是壞掉。
... B20: 目前待補的資料 | C20: 一、助理與醫護長名單尚未提供,助理班表/打卡匯入/出勤紀錄/月結統計四個分頁 已經建好結構但沒有人員資料,名單一到即可直接灌入。 二、助理的班別時間(早班/晚班/中班/行政班)目前是暫定值,需要確認。 三、員工編號目前為暫編 D001~D027,若人事或打卡系統另有編號應以那套為準。 四、官網門診表有星號註記者(並非每週固定)需逐一向院所確認。

Sheet 設定
B1: 設定表(總部維護,各院所請勿修改)
B2: 本期年月 | C2: 2026 | D2: 10 | E2: ← 整份檔案的日期、星期都以這裡為準
B4: 一、助理/醫護長 班別代碼(工時制) | W4: 六、2026 年國定假日(全院休診,班表自動填「國」)
B5: 代碼 | C5: 名稱 | D5: 應到 | E5: 應退 | F5: 休息(分) | G5: 排班工時 | H5: 計出勤 | I5: 類別 | N5: 星期對照 | Q5: 醫師編號(下拉用) | S5: 助理/醫護長編號(下拉用) | W5: 日期 | X5: 名稱 | Y5: 類別 | AP5: 醫師週班表下拉選單來源(自動產生,勿刪)
B6: 早 | C6: 早班 | D6: 0.375 | E6: 0.5 | F6: 0 | G6: 3 | H6: 1 | I6: 上班 | N6: 1 | O6: 日 | Q6: D001 | W6: 46023 | X6: 中華民國開國紀念日(週四) | AP6: 悅
B7: 午 | C7: 午班 | D7: 0.58333333 | E7: 0.70833333 | F7: 0 | G7: 3 | H7: 1 | I7: 上班 | N7: 2 | O7: 一 | Q7: D002 | W7: 46068 | X7: 小年夜(週日) | AP7: 睿
B8: 晚 | C8: 晚班 | D8: 0.75 | E8: 0.875 | F8: 0 | G8: 3 | H8: 1 | I8: 上班 | N8: 3 | O8: 二 | Q8: D003 | W8: 46069 | X8: 除夕(週一) | AP8: 匯
B9: 早午 | C9: 早班+午班 | D9: 0.375 | E9: 0.70833333 | F9: 120 | G9: 6 | H9: 1 | I9: 上班 | N9: 4 | O9: 三 | Q9: D004 | W9: 46070 | X9: 春節 初一(週二) | AP9: 曜
B10: 午晚 | C10: 午班+晚班 | D10: 0.58333333 | E10: 0.875 | F10: 60 | G10: 6 | H10: 1 | I10: 上班 | N10: 5 | O10: 四 | Q10: D005 | W10: 46071 | X10: 春節 初二(週三) | AP10: 寶
B11: 早晚 | C11: 早班+晚班 | D11: 0.375 | E11: 0.875 | F11: 360 | G11: 6 | H11: 1 | I11: 上班 | N11: 6 | O11: 五 | Q11: D006 | W11: 46072 | X11: 春節 初三(週四) | AP11: 悅(隔)
B12: 全日 | C12: 早+午+晚 | D12: 0.375 | E12: 0.875 | F12: 180 | G12: 9 | H12: 1 | I12: 上班 | N12: 7 | O12: 六 | Q12: D007 | W12: 46080 | X12: 和平紀念日 補假(週五) | Y12: 補假 | AP12: 睿(隔)
B13: 支 | C13: 支援他院 | F13: 0 | G13: 6 | H13: 1 | I13: 上班 | Q13: D008 | W13: 46081 | X13: 和平紀念日(週六) | AP13: 匯(隔)
B14: 訓 | C14: 教育訓練/會議 | F14: 0 | G14: 6 | H14: 1 | I14: 上班 | Q14: D009 | W14: 46115 | X14: 兒童節 補假(週五) | Y14: 補假 | AP14: 曜(隔)
B15: OFF | C15: 排休 | F15: 0 | G15: 0 | H15: 0 | I15: 休假 | Q15: D010 | W15: 46116 | X15: 兒童節(週六) | AP15: 寶(隔)
B16: 特 | C16: 特休 | F16: 0 | G16: 0 | H16: 0 | I16: 休假 | Q16: D011 | W16: 46117 | X16: 清明節(週日) | AP16: 寶(不定)
B17: 病 | C17: 病假 | F17: 0 | G17: 0 | H17: 0 | I17: 休假 | Q17: D012 | W17: 46118 | X17: 清明節 補假(週一) | Y17: 補假 | AP17: 悅(不定)
B18: 事 | C18: 事假 | F18: 0 | G18: 0 | H18: 0 | I18: 休假 | Q18: D013 | W18: 46143 | X18: 勞動節(週五) | AP18: 悅(註)
B19: 公 | C19: 公假 | F19: 0 | G19: 0 | H19: 0 | I19: 休假 | Q19: D014 | W19: 46192 | X19: 端午節(週五) | AP19: 悅/匯
B20: 國 | C20: 國定假日 | F20: 0 | G20: 0 | H20: 0 | I20: 休假 | Q20: D015 | W20: 46290 | X20: 中秋節(週五) | AP20: 悅/睿
B21: 休 | C21: 休診 | F21: 0 | G21: 0 | H21: 0 | I21: 休假 | Q21: D016 | W21: 46293 | X21: 教師節(週一) | AP21: 睿/曜
B22: ※ 有固定時段的代碼必須滿足「應退 − 應到 − 休息 = 排班工時」,否則出勤紀錄會算出不存在的加班。建置腳本會自動檢查。 | Q22: D017 | W22: 46304 | X22: 國慶日 補假(週五) | Y22: 補假 | AP22: 訓
Q23: D018 | W23: 46305 | X23: 國慶日(週六) | AP23: OFF
B24: 二、醫師診次代碼(醫師班表用:一格填一個代碼) | E24: 二之二、醫師週班表的標記(母表專用) | Q24: D019 | W24: 46320 | X24: 台灣光復節(週日) | AP24: 特
B25: 代碼 | C25: 意義 | E25: 寫法 | F25: 意思 | G25: 舉例說明 | Q25: D020 | W25: 46321 | X25: 台灣光復節 補假(週一) | Y25: 補假 | AP25: 病
B26: 悅 | C26: 晶悅牙醫 | E26: 悅 | F26: 每週固定 | G26: 每一週的這個診次都在晶悅 | Q26: D021 | W26: 46381 | X26: 行憲紀念日(週五) | AP26: 事
B27: 睿 | C27: 晶睿牙醫 | E27: 悅(隔) | F27: 隔週看診 | G27: 單數週在晶悅,雙數週這個診次不排 | Q27: D022 | AP27: 公
B28: 匯 | C28: 晶匯牙醫 | E28: 悅/睿 | F28: 兩間院所輪替 | G28: 斜線前 = 單數週、斜線後 = 雙數週(全表共四組) | Q28: D023 | AP28: 國
B29: 曜 | C29: 晶曜牙醫 | E29: 寶(不定) | F29: 非每週固定 | G29: 官網註明「詳情請聯繫院所」,需逐一向院所確認 | Q29: D024 | AP29: 休
B30: 寶 | C30: 寶貝牙牙醫 | E30: 悅(註) | F30: 有附加條件 | G30: 條件寫在該列最右邊的附註欄 | Q30: D025
B31: 訓 | C31: 教育訓練 / 學會 | E31: OFF 特 病 | F31: 休假類 | G31: 整個診次請假,寫法與醫師班表相同 | Q31: D026
B32: OFF | C32: 排休 | E32: ※ 單數/雙數週以計算參數區的「隔週基準日」起算,跨月跨年連續不會斷。 | Q32: D027
B33: 特 | C33: 特休 | E33: ※ 週班表的資料格有下拉選單,但不強制——輸入清單外的寫法只會跳提醒,按「是」照樣存入。
B34: 病 | C34: 病假
B35: 事 | C35: 事假
B36: 公 | C36: 公假
B37: 國 | C37: 國定假日
B38: 休 | C38: 休診
B39: ※ 醫師班表一格 = 一個診次。填院所代碼表示該診次在哪間看診,填休假代碼表示該診次請假。
B40: ※ 「醫師週班表」除了上面這些代碼,還會用到右邊那幾種標記——那是母表,要表示隔週與輪替,所以下拉選項比較多。
B42: 三、計算參數(全體系一致) | W42: ※ ⚠ 這份是草稿,務必與行政院人事行政總處公告的「政府行政機關辦公日曆表」核對。法定紀念日日期可信度高,但補假與調整放假(彈性放假)每年公告,以官方版本為準。
...

Sheet 醫師週班表
A1: 醫師週班表(固定門診表 · 這是排月班的母表)
A2: 資料來源:官網五間院所門診表頁面,由原始碼直接解析產生(231 筆逐格比對一致)。格內寫法見「設定」分頁的「二之二、醫師週班表的標記」。改這裡等於改固定門診:「醫師班表」整個月的對應格子會立刻跟著變,月結也會。
A3: 員工編號 | B3: 姓名 | C3: 週一 | F3: 週二 | I3: 週三 | L3: 週四 | O3: 週五 | R3: 週六 | V3: 附註
C4: 早 | D4: 午 | E4: 晚 | F4: 早 | G4: 午 | H4: 晚 | I4: 早 | J4: 午 | K4: 晚 | L4: 早 | M4: 午 | N4: 晚 | O4: 早 | P4: 午 | Q4: 晚 | R4: 早 | S4: 午 | T4: 晚
A5: D001 | B5: 林智俊 | D5: 悅 | E5: 悅 | F5: 曜 | G5: 曜 | I5: 悅 | J5: 悅 | K5: 悅 | M5: 匯 | N5: 匯 | P5: 悅 | Q5: 悅 | R5: 悅(隔)
A6: D002 | B6: 劉立德 | C6: 曜 | D6: 曜 | E6: 曜 | G6: 睿 | H6: 睿 | I6: 睿/曜 | J6: 睿/曜 | L6: 曜 | M6: 曜 | N6: 曜 | P6: 睿 | Q6: 睿
A7: D003 | B7: 王泳泉 | D7: 悅/睿 | E7: 悅/睿 | J7: 悅 | K7: 悅 | R7: 悅
A8: D004 | B8: 劉玠旻 | D8: 悅(隔) | F8: 悅 | G8: 悅 | J8: 曜 | L8: 睿 | M8: 睿
A9: D005 | B9: 陳志僑 | F9: 悅 | G9: 悅 | H9: 睿
A10: D006 | B10: 黃榆鈞 | G10: 寶(不定) | H10: 寶 | M10: 悅(註) | N10: 悅(註) | R10: 寶(不定) | S10: 寶(不定) | V10: 黃榆鈞:每月1日15:30後 / 黃榆鈞:每月1日
A11: D007 | B11: 温翊君 | G11: 悅 | H11: 悅 | R11: 悅 | S11: 悅
A12: D008 | B12: 林紫亭 | F12: 悅 | G12: 悅 | H12: 悅 | R12: 悅 | S12: 悅
A13: D009 | B13: 陳昺元 | I13: 悅 | J13: 悅 | K13: 悅 | M13: 寶 | N13: 寶 | O13: 匯 | P13: 匯 | Q13: 匯 | R13: 悅/匯 | S13: 悅/匯
A14: D010 | B14: 蔡季軒 | C14: 悅 | D14: 悅 | E14: 悅 | G14: 悅 | H14: 悅 | I14: 悅 | J14: 悅 | O14: 悅 | P14: 悅 | Q14: 悅
A15: D011 | B15: 温健成 | D15: 匯 | E15: 匯 | F15: 睿 | G15: 睿 | H15: 睿 | J15: 匯 | K15: 匯 | L15: 睿 | M15: 睿 | N15: 睿 | R15: 睿(隔) | S15: 睿(隔)
A16: D012 | B16: 陳立軒 | D16: 睿 | E16: 睿 | F16: 匯 | G16: 曜 | H16: 曜 | J16: 睿 | K16: 睿 | L16: 匯 | M16: 匯 | N16: 匯 | O16: 曜 | P16: 曜 | Q16: 曜 | R16: 曜(隔) | S16: 曜(隔)
A17: D013 | B17: 朱柏非 | C17: 悅 | D17: 悅 | E17: 悅 | I17: 匯 | J17: 匯 | K17: 匯 | M17: 寶 | N17: 寶 | O17: 悅 | P17: 悅 | Q17: 悅 | R17: 悅/匯 | S17: 悅/匯
A18: D014 | B18: 鄭漢賢 | C18: 悅 | D18: 悅 | E18: 悅 | F18: 匯 | G18: 匯 | H18: 匯 | L18: 悅 | M18: 悅 | O18: 匯 | P18: 匯 | Q18: 匯 | R18: 悅 | S18: 悅
A19: D015 | B19: 徐平 | D19: 曜 | E19: 曜 | G19: 悅 | H19: 悅 | J19: 曜 | K19: 曜 | M19: 悅 | N19: 悅 | P19: 曜 | Q19: 曜 | R19: 曜(隔) | S19: 曜(隔)
A20: D016 | B20: 賴敏傑 | C20: 睿 | D20: 睿 | E20: 睿 | L20: 睿
A21: D017 | B21: 吳柏賢 | C21: 曜 | D21: 曜 | E21: 曜 | I21: 曜 | J21: 曜 | K21: 曜 | L21: 睿 | M21: 睿 | N21: 睿 | P21: 曜 | Q21: 曜 | R21: 睿 | S21: 睿
A22: D018 | B22: 許博諺 | C22: 睿 | D22: 睿 | E22: 睿 | F22: 曜 | G22: 曜 | H22: 曜 | L22: 曜 | M22: 曜 | N22: 曜 | P22: 睿 | Q22: 睿 | R22: 曜 | S22: 曜
A23: D019 | B23: 翁崎紘 | P23: 悅(不定) | Q23: 悅(不定)
A24: D020 | B24: 余柏萱 | F24: 睿 | G24: 睿 | H24: 睿 | I24: 睿 | J24: 睿 | K24: 睿 | O24: 睿 | P24: 寶 | Q24: 寶 | R24: 睿 | S24: 睿
A25: D021 | B25: 鄭博文 | G25: 悅 | H25: 悅 | I25: 悅 | J25: 悅 | K25: 悅 | L25: 悅 | M25: 悅 | N25: 悅 | P25: 悅 | Q25: 悅 | R25: 悅 | S25: 悅
A26: D022 | B26: 黃育亭 | J26: 寶 | K26: 寶 | R26: 寶(不定) | S26: 寶(不定)
A27: D023 | B27: 黃婷愉 | R27: 寶(不定) | S27: 寶(不定)
A28: D024 | B28: 林紓安 | D28: 寶 | E28: 寶 | J28: 匯(隔) | K28: 匯(隔) | P28: 寶 | Q28: 寶
A29: D025 | B29: 陳爵安 | C29: 睿 | I29: 睿 | K29: 睿 | O29: 睿 | P29: 睿 | Q29: 睿 | R29: 睿 | S29: 睿
A30: D026 | B30: 吳冠廷 | C30: 匯 | D30: 匯 | E30: 匯 | L30: 匯 | M30: 匯 | N30: 匯
A31: D027 | B31: 楊孟庭 | D31: 匯(隔) | E31: 匯(隔) | R31: 匯(隔) | S31: 匯(隔)
B32: =IFERROR(INDEX(設定!$C$62:$C$201,MATCH($A32,設定!$B$62:$B$201,0)),"")
B33: =IFERROR(INDEX(設定!$C$62:$C$201,MATCH($A33,設定!$B$62:$B$201,0)),"")
B34: =IFERROR(INDEX(設定!$C$62:$C$201,MATCH($A34,設定!$B$62:$B$201,0)),"")
B35: =IFERROR(INDEX(設定!$C$62:$C$201,MATCH($A35,設定!$B$62:$B$201,0)),"")
B36: =IFERROR(INDEX(設定!$C$62:$C$201,MATCH($A36,設定!$B$62:$B$201,0)),"")
B37: =IFERROR(INDEX(設定!$C$62:$C$201,MATCH($A37,設定!$B$62:$B$201,0)),"")
B38: =IFERROR(INDEX(設定!$C$62:$C$201,MATCH($A38,設定!$B$62:$B$201,0)),"")
B39: =IFERROR(INDEX(設定!$C$62:$C$201,MATCH($A39,設定!$B$62:$B$201,0)),"")
B40: =IFERROR(INDEX(設定!$C$62:$C$201,MATCH($A40,設定!$B$62:$B$201,0)),"")
...

Sheet 醫師班表
A1: 醫師班表(診次制 · 一格 = 一個診次 · 已依週班表填好本月)
A2: 期間 | B2: 2026 年 10 月 | D2: 圖例: | E2: 悅 晶悅 | I2: 睿 晶睿 | M2: 匯 晶匯 | Q2: 曜 晶曜 | U2: 寶 寶貝牙
A3: 員工編號 | B3: 姓名 | C3: 專科 | D3: 職務 | E3: 1 | H3: 2 | K3: 3 | N3: 4 | Q3: 5 | T3: 6 | W3: 7 | Z3: 8 | AC3: 9 | AF3: 10 | AI3: 11 | AL3: 12 | AO3: 13 | AR3: 14 | AU3: 15 | AX3: 16 | BA3: 17 | BD3: 18 | BG3: 19 | BJ3: 20 | BM3: 21 | BP3: 22 | BS3: 23 | BV3: 24 | BY3: 25 | CB3: 26 | CE3: 27 | CH3: 28 | CK3: 29 | CN3: 30 | CQ3: 31
E4: 四 | F4: 四 | G4: 四 | H4: 五 | I4: 五 | J4: 五 | K4: 六 | L4: 六 | M4: 六 | N4: 日 | O4: 日 | P4: 日 | Q4: 一 | R4: 一 | S4: 一 | T4: 二 | U4: 二 | V4: 二 | W4: 三 | X4: 三 | Y4: 三 | Z4: 四 | AA4: 四 | AB4: 四 | AC4: 五 | AD4: 五 | AE4: 五 | AF4: 六 | AG4: 六 | AH4: 六 | AI4: 日 | AJ4: 日 | AK4: 日 | AL4: 一 | AM4: 一 | AN4: 一 | AO4: 二 | AP4: 二 | AQ4: 二 | AR4: 三 | AS4: 三 | AT4: 三 | AU4: 四 | AV4: 四 | AW4: 四 | AX4: 五 | AY4: 五 | AZ4: 五 | BA4: 六 | BB4: 六 | BC4: 六 | BD4: 日 | BE4: 日 | BF4: 日 | BG4: 一 | BH4: 一 | BI4: 一 | BJ4: 二 | BK4: 二 | BL4: 二 | BM4: 三 | BN4: 三 | BO4: 三 | BP4: 四 | BQ4: 四 | BR4: 四 | BS4: 五 | BT4: 五 | BU4: 五 | BV4: 六 | BW4: 六 | BX4: 六 | BY4: 日 | BZ4: 日 | CA4: 日 | CB4: 一 | CC4: 一 | CD4: 一 | CE4: 二 | CF4: 二 | CG4: 二 | CH4: 三 | CI4: 三 | CJ4: 三 | CK4: 四 | CL4: 四 | CM4: 四 | CN4: 五 | CO4: 五 | CP4: 五 | CQ4: 六 | CR4: 六 | CS4: 六
E5: 早 | F5: 午 | G5: 晚 | H5: 早 | I5: 午 | J5: 晚 | K5: 早 | L5: 午 | M5: 晚 | N5: 早 | O5: 午 | P5: 晚 | Q5: 早 | R5: 午 | S5: 晚 | T5: 早 | U5: 午 | V5: 晚 | W5: 早 | X5: 午 | Y5: 晚 | Z5: 早 | AA5: 午 | AB5: 晚 | AC5: 早 | AD5: 午 | AE5: 晚 | AF5: 早 | AG5: 午 | AH5: 晚 | AI5: 早 | AJ5: 午 | AK5: 晚 | AL5: 早 | AM5: 午 | AN5: 晚 | AO5: 早 | AP5: 午 | AQ5: 晚 | AR5: 早 | AS5: 午 | AT5: 晚 | AU5: 早 | AV5: 午 | AW5: 晚 | AX5: 早 | AY5: 午 | AZ5: 晚 | BA5: 早 | BB5: 午 | BC5: 晚 | BD5: 早 | BE5: 午 | BF5: 晚 | BG5: 早 | BH5: 午 | BI5: 晚 | BJ5: 早 | BK5: 午 | BL5: 晚 | BM5: 早 | BN5: 午 | BO5: 晚 | BP5: 早 | BQ5: 午 | BR5: 晚 | BS5: 早 | BT5: 午 | BU5: 晚 | BV5: 早 | BW5: 午 | BX5: 晚 | BY5: 早 | BZ5: 午 | CA5: 晚 | CB5: 早 | CC5: 午 | CD5: 晚 | CE5: 早 | CF5: 午 | CG5: 晚 | CH5: 早 | CI5: 午 | CJ5: 晚 | CK5: 早 | CL5: 午 | CM5: 晚 | CN5: 早 | CO5: 午 | CP5: 晚 | CQ5: 早 | CR5: 午 | CS5: 晚
A6: D001 | B6: 林智俊 | C6: 牙周植牙專科 | D6: 晶悅院長 | E6: =IF(E$59="X","",IF(E$59<>"",E$59,IF(IFERROR(INDEX(醫師週班表!$C$5:$T$44,$CU6,E$57),"")=0,"",IF(MID(IFERROR(INDEX(醫師週班表!$C$5:$T$44,$CU6,E$57),""),2,1)="/",MID(IFERROR(INDEX(醫師週班表!$C$5:$T$44,$CU6,E$57),""),1+E$58*2,1),IF(MID(IFERROR(INDEX(醫師週班表!$C$5:$T$44,$CU6,E$57),""),3,1)="隔",IF(E$58=0,LEFT(IFERROR(INDEX(醫師週班表!$C$5:$T$44,$CU6,E$57),""),1),""),IF(MID(IFERROR(INDEX(醫師週班表!$C$5:$T$44,$CU6,E$57),""),2,1)="(",LEFT(IFERROR(INDEX(醫師週班表!$C$5:$T$44,$CU6,E$57),""),1),IFERROR(INDEX(醫師週班表!$C$5:$T$44,$CU6,E$57),""))))))) | F6: =IF(F$59="X","",IF(F$59<>"",F$59,IF(IFERROR(INDEX(醫師週班表!$C$5:$T$44,$CU6,F$57),"")=0,"",IF(MID(IFERROR(INDEX(醫師週班表!$C$5:$T$44,$CU6,F$57),""),2,1)="/",MID(IFERROR(INDEX(醫師週班表!$C$5:$T$44,$CU6,F$57),""),1+F$58*2,1),IF(MID(IFERROR(INDEX(醫師週班表!$C$5:$T$44,$CU6,F$57),""),3,1)="隔",IF(F$58=0,LEFT(IFERROR(INDEX(醫師週班表!$C$5:$T$44,$CU6,F$57),""),1),""),IF(MID(IFERROR(INDEX(醫師週班表!$C$5:$T$44,$CU6,F$57),""),2,1)="(",LEFT(IFERROR(INDEX(醫師週班表!$C$5:$T$44,$CU6,F$57),""),1),IFERROR(INDEX(醫師週班表!$C$5:$T$44,$CU6,F$57),""))))))) | G6: =IF(G$59="X","",IF(G$59<>"",G$59,IF(IFERROR(INDEX(醫師週班表!$C$5:$T$44,$CU6,G$57),"")=0,"",IF(MID(IFERROR(INDEX(醫師週班表!$C$5:$T$44,$CU6,G$57),""),2,1)="/",MID(IFERROR(INDEX(醫師週班表!$C$5:$T$44,$CU6,G$57),""),1+G$58*2,1),IF(MID(IFERROR(INDEX(醫師週班表!$C$5:$T$44,$CU6,G$57),""),3,1)="隔",IF(G$58=0,LEFT(IFERROR(INDEX(醫師週班表!$C$5:$T$44,$CU6,G$57),""),1),""),IF(MID(IFERROR(INDEX(醫師週班表!$C$5:$T$44,$CU6,G$57),""),2,1)="(",LEFT(IFERROR(INDEX(醫師週班表!$C$5:$T$44,$CU6,G$57),""),1),IFERROR(INDEX(醫師週班表!$C$5:$T$44,$CU6,G$57),""))))))) | H6: =IF(H$59="X","",IF(H$59<>"",H$59,IF(IFERROR(INDEX(醫師週班表!$C$5:$T$44,$CU6,H$57),"")=0,"",IF(MID(IFERROR(INDEX(醫師週班表!$C$5:$T$44,$CU6,H$57),""),2,1)="/",MID(IFERROR(INDEX(醫師週班表!$C$5:$T$44,$CU6,H$57),""),1+H$58*2,1),IF(MID(IFERROR(INDEX(醫師週班表!$C$5:$T$44,$CU6,H$57),""),3,1)="隔",IF(H$58=0,LEFT(IFERROR(INDEX(醫師週班表!$C$5:$T$44,$CU6,H$57),""),1),""),IF(MID(IFERROR(INDEX(醫師週班表!$C$5:$T$44,$CU6,H$57),""),2,1)="(",LEFT(IFERROR(INDEX(醫師週班表!$C$5:$T$44,$CU6,H$57),""),1),IFERROR(INDEX(醫師週班表!$C$5:$T$44,$CU6,H$57),""))))))) | I6: =IF(I$59="X","",IF(I$59<>"",I$59,IF(IFERROR(INDEX(醫師週班表!$C$5:$T$44,$CU6,I$57),"")=0,"",IF(MID(IFERROR(INDEX(醫師週班表!$C$5:$T$44,$CU6,I$57),""),2,1)="/",MID(IFERROR(INDEX(醫師週班表!$C$5:$T$44,$CU6,I$57),""),1+I$58*2,1),IF(MID(IFERROR(INDEX(醫師週班表!$C$5:$T$44,$CU6,I$57),""),3,1)="隔",IF(I$58=0,LEFT(IFERROR(INDEX(醫師週班表!$C$5:$T$44,$CU6,I$57),""),1),""),IF(MID(IFERROR(INDEX(醫師週班表!$C$5:$T$44,$CU6,I$57),""),2,1)="(",LEFT(IFERROR(INDEX(醫師週班表!$C$5:$T$44,$CU6,I$57),""),1),IFERROR(INDEX(醫師週班表!$C$5:$T$44,$CU6,I$57),""))))))) | J6: =IF(J$59="X","",IF(J$59<>"",J$59,IF(IFERROR(INDEX(醫師週班表!$C$5:$T$44,$CU6,J$57),"")=0,"",IF(MID(IFERROR(INDEX(醫師週班表!$C$5:$T$44,$CU6,J$57),""),2,1)="/",MID(IFERROR(INDEX(醫師週班表!$C$5:$T$44,$CU6,J$57),""),1+J$58*2,1),IF(MID(IFERROR(INDEX(醫師週班表!$C$5:$T$44,$CU6,J$57),""),3,1)="隔",IF(J$58=0,LEFT(IFERROR(INDEX(醫師週班表!$C$5:$T$44,$CU6,J$57),""),1),""),IF(MID(IFERROR(INDEX(醫師週班表!$C$5:$T$44,$CU6,J$57),""),2,1)="(",LEFT(IFERROR(INDEX(醫師週班表!$C$5:$T$44,$CU6,J$57),""),1),IFERROR(INDEX(醫師週班表!$C$5:$T$44,$CU6,J$57),""))))))) | K6: =IF(K$59="X","",IF(K$59<>"",K$59,IF(IFERROR(INDEX(醫師週班表!$C$5:$T$44,$CU6,K$57),"")=0,"",IF(MID(IFERROR(INDEX(醫師週班表!$C$5:$T$44,$CU6,K$57),""),2,1)="/",MID(IFERROR(INDEX(醫師週班表!$C$5:$T$44,$CU6,K$57),""),1+K$58*2,1),IF(MID(IFERROR(INDEX(醫師週班表!$C$5:$T$44,$CU6,K$57),""),3,1)="隔",IF(K$58=0,LEFT(IFERROR(INDEX(醫師週班表!$C$5:$T$44,$CU6,K$57),""),1),""),IF(MID(IFERROR(INDEX(醫師週班表!$C$5:$T$44,$CU6,K$57),""),2,1)="(",LEFT(IFERROR(INDEX(醫師週班表!$C$5:$T$44,$CU6,K$57),""),1),IFERROR(INDEX(醫師週班表!$C$5:$T$44,$CU6,K$57),""))))))) | L6: =IF(L$59="X","",IF(L$59<>"",L$59,IF(IFERROR(INDEX(醫師週班表!$C$5:$T$44,$CU6,L$57),"")=0,"",IF(MID(IFERROR(INDEX(醫師週班表!$C$5:$T$44,$CU6,L$57),""),2,1)="/",MID(IFERROR(INDEX(醫師週班表!$C$5:$T$44,$CU6,L$57),""),1+L$58*2,1),IF(MID(IFERROR(INDEX(醫師週班表!$C$5:$T$44,$CU6,L$57),""),3,1)="隔",IF(L$58=0,LEFT(IFERROR(INDEX(醫師週班表!$C$5:$T$44,$CU6,L$57),""),1),""),IF(MID(IFERROR(INDEX(醫師週班表!$C$5:$T$44,$CU6,L$57),""),2,1)="(",LEFT(IFERROR(INDEX(醫師週班表!$C$5:$T$44,$CU6,L$57),""),1),IFERROR(INDEX(醫師週班表!$C$5:$T$44,$CU6,L$57),""))))))) | ... CS6: =IF(CS$59="X","",IF(CS$59<>"",CS$59,IF(IFERROR(INDEX(醫師週班表!$C$5:$T$44,$CU6,CS$57),"")=0,"",IF(MID(IFERROR(INDEX(醫師週班表!$C$5:$T$44,$CU6,CS$57),""),2,1)="/",MID(IFERROR(INDEX(醫師週班表!$C$5:$T$44,$CU6,CS$57),""),1+CS$58*2,1),IF(MID(IFERROR(INDEX(醫師週班表!$C$5:$T$44,$CU6,CS$57),""),3,1)="隔",IF(CS$58=0,LEFT(IFERROR(INDEX(醫師週班表!$C$5:$T$44,$CU6,CS$57),""),1),""),IF(MID(IFERROR(INDEX(醫師週班表!$C$5:$T$44,$CU6,CS$57),""),2,1)="(",LEFT(IFERROR(INDEX(醫師週班表!$C$5:$T$44,$CU6,CS$57),""),1),IFERROR(INDEX(醫師週班表!$C$5:$T$44,$CU6,CS$57),""))))))) | CU6: =IFERROR(MATCH($A6,醫師週班表!$A$5:$A$44,0),0)
A7: D002 | B7: 劉立德 | C7: 植牙專科 家庭牙醫專科 | D7: 晶曜院長 | E7: =IF(E$59="X","",IF(E$59<>"",E$59,IF(IFERROR(INDEX(醫師週班表!$C$5:$T$44,$CU7,E$57),"")=0,"",IF(MID(IFERROR(INDEX(醫師週班表!$C$5:$T$44,$CU7,E$57),""),2,1)="/",MID(IFERROR(INDEX(醫師週班表!$C$5:$T$44,$CU7,E$57),""),1+E$58*2,1),IF(MID(IFERROR(INDEX(醫師週班表!$C$5:$T$44,$CU7,E$57),""),3,1)="隔",IF(E$58=0,LEFT(IFERROR(INDEX(醫師週班表!$C$5:$T$44,$CU7,E$57),""),1),""),IF(MID(IFERROR(INDEX(醫師週班表!$C$5:$T$44,$CU7,E$57),""),2,1)="(",LEFT(IFERROR(INDEX(醫師週班表!$C$5:$T$44,$CU7,E$57),""),1),IFERROR(INDEX(醫師週班表!$C$5:$T$44,$CU7,E$57),""))))))) | F7: =IF(F$59="X","",IF(F$59<>"",F$59,IF(IFERROR(INDEX(醫師週班表!$C$5:$T$44,$CU7,F$57),"")=0,"",IF(MID(IFERROR(INDEX(醫師週班表!$C$5:$T$44,$CU7,F$57),""),2,1)="/",MID(IFERROR(INDEX(醫師週班表!$C$5:$T$44,$CU7,F$57),""),1+F$58*2,1),IF(MID(IFERROR(INDEX(醫師週班表!$C$5:$T$44,$CU7,F$57),""),3,1)="隔",IF(F$58=0,LEFT(IFERROR(INDEX(醫師週班表!$C$5:$T$44,$CU7,F$57),""),1),""),IF(MID(IFERROR(INDEX(醫師週班表!$C$5:$T$44,$CU7,F$57),""),2,1)="(",LEFT(IFERROR(INDEX(醫師週班表!$C$5:$T$44,$CU7,F$57),""),1),IFERROR(INDEX(醫師週班表!$C$5:$T$44,$CU7,F$57),""))))))) | G7: =IF(G$59="X","",IF(G$59<>"",G$59,IF(IFERROR(INDEX(醫師週班表!$C$5:$T$44,$CU7,G$57),"")=0,"",IF(MID(IFERROR(INDEX(醫師週班表!$C$5:$T$44,$CU7,G$57),""),2,1)="/",MID(IFERROR(INDEX(醫師週班表!$C$5:$T$44,$CU7,G$57),""),1+G$58*2,1),IF(MID(IFERROR(INDEX(醫師週班表!$C$5:$T$44,$CU7,G$57),""),3,1)="隔",IF(G$58=0,LEFT(IFERROR(INDEX(醫師週班表!$C$5:$T$44,$CU7,G$57),""),1),""),IF(MID(IFERROR(INDEX(醫師週班表!$C$5:$T$44,$CU7,G$57),""),2,1)="(",LEFT(IFERROR(INDEX(醫師週班表!$C$5:$T$44,$CU7,G$57),""),1),IFERROR(INDEX(醫師週班表!$C$5:$T$44,$CU7,G$57),""))))))) | H7: =IF(H$59="X","",IF(H$59<>"",H$59,IF(IFERROR(INDEX(醫師週班表!$C$5:$T$44,$CU7,H$57),"")=0,"",IF(MID(IFERROR(INDEX(醫師週班表!$C$5:$T$44,$CU7,H$57),""),2,1)="/",MID(IFERROR(INDEX(醫師週班表!$C$5:$T$44,$CU7,H$57),""),1+H$58*2,1),IF(MID(IFERROR(INDEX(醫師週班表!$C$5:$T$44,$CU7,H$57),""),3,1)="隔",IF(H$58=0,LEFT(IFERROR(INDEX(醫師週班表!$C$5:$T$44,$CU7,H$57),""),1),""),IF(MID(IFERROR(INDEX(醫師週班表!$C$5:$T$44,$CU7,H$57),""),2,1)="(",LEFT(IFERROR(INDEX(醫師週班表!$C$5:$T$44,$CU7,H$57),""),1),IFERROR(INDEX(醫師週班表!$C$5:$T$44,$CU7,H$57),""))))))) | I7: =IF(I$59="X","",IF(I$59<>"",I$59,IF(IFERROR(INDEX(醫師週班表!$C$5:$T$44,$CU7,I$57),"")=0,"",IF(MID(IFERROR(INDEX(醫師週班表!$C$5:$T$44,$CU7,I$57),""),2,1)="/",MID(IFERROR(INDEX(醫師週班表!$C$5:$T$44,$CU7,I$57),""),1+I$58*2,1),IF(MID(IFERROR(INDEX(醫師週班表!$C$5:$T$44,$CU7,I$57),""),3,1)="隔",IF(I$58=0,LEFT(IFERROR(INDEX(醫師週班表!$C$5:$T$44,$CU7,I$57),""),1),""),IF(MID(IFERROR(INDEX(醫師週班表!$C$5:$T$44,$CU7,I$57),""),2,1)="(",LEFT(IFERROR(INDEX(醫師週班表!$C$5:$T$44,$CU7,I$57),""),1),IFERROR(INDEX(醫師週班表!$C$5:$T$44,$CU7,I$57),""))))))) | J7: =IF(J$59="X","",IF(J$59<>"",J$59,IF(IFERROR(INDEX(醫師週班表!$C$5:$T$44,$CU7,J$57),"")=0,"",IF(MID(IFERROR(INDEX(醫師週班表!$C$5:$T$44,$CU7,J$57),""),2,1)="/",MID(IFERROR(INDEX(醫師週班表!$C$5:$T$44,$CU7,J$57),""),1+J$58*2,1),IF(MID(IFERROR(INDEX(醫師週班表!$C$5:$T$44,$CU7,J$57),""),3,1)="隔",IF(J$58=0,LEFT(IFERROR(INDEX(醫師週班表!$C$5:$T$44,$CU7,J$57),""),1),""),IF(MID(IFERROR(INDEX(醫師週班表!$C$5:$T$44,$CU7,J$57),""),2,1)="(",LEFT(IFERROR(INDEX(醫師週班表!$C$5:$T$44,$CU7,J$57),""),1),IFERROR(INDEX(醫師週班表!$C$5:$T$44,$CU7,J$57),""))))))) | K7: =IF(K$59="X","",IF(K$59<>"",K$59,IF(IFERROR(INDEX(醫師週班表!$C$5:$T$44,$CU7,K$57),"")=0,"",IF(MID(IFERROR(INDEX(醫師週班表!$C$5:$T$44,$CU7,K$57),""),2,1)="/",MID(IFERROR(INDEX(醫師週班表!$C$5:$T$44,$CU7,K$57),""),1+K$58*2,1),IF(MID(IFERROR(INDEX(醫師週班表!$C$5:$T$44,$CU7,K$57),""),3,1)="隔",IF(K$58=0,LEFT(IFERROR(INDEX(醫師週班表!$C$5:$T$44,$CU7,K$57),""),1),""),IF(MID(IFERROR(INDEX(醫師週班表!$C$5:$T$44,$CU7,K$57),""),2,1)="(",LEFT(IFERROR(INDEX(醫師週班表!$C$5:$T$44,$CU7,K$57),""),1),IFERROR(INDEX(醫師週班表!$C$5:$T$44,$CU7,K$57),""))))))) | L7: =IF(L$59="X","",IF(L$59<>"",L$59,IF(IFERROR(INDEX(醫師週班表!$C$5:$T$44,$CU7,L$57),"")=0,"",IF(MID(IFERROR(INDEX(醫師週班表!$C$5:$T$44,$CU7,L$57),""),2,1)="/",MID(IFERROR(INDEX(醫師週班表!$C$5:$T$44,$CU7,L$57),""),1+L$58*2,1),IF(MID(IFERROR(INDEX(醫師週班表!$C$5:$T$44,$CU7,L$57),""),3,1)="隔",IF(L$58=0,LEFT(IFERROR(INDEX(醫師週班表!$C$5:$T$44,$CU7,L$57),""),1),""),IF(MID(IFERROR(INDEX(醫師週班表!$C$5:$T$44,$CU7,L$57),""),2,1)="(",LEFT(IFERROR(INDEX(醫師週班表!$C$5:$T$44,$CU7,L$57),""),1),IFERROR(INDEX(醫師週班表!$C$5:$T$44,$CU7,L$57),""))))))) | ... CS7: =IF(CS$59="X","",IF(CS$59<>"",CS$59,IF(IFERROR(INDEX(醫師週班表!$C$5:$T$44,$CU7,CS$57),"")=0,"",IF(MID(IFERROR(INDEX(醫師週班表!$C$5:$T$44,$CU7,CS$57),""),2,1)="/",MID(IFERROR(INDEX(醫師週班表!$C$5:$T$44,$CU7,CS$57),""),1+CS$58*2,1),IF(MID(IFERROR(INDEX(醫師週班表!$C$5:$T$44,$CU7,CS$57),""),3,1)="隔",IF(CS$58=0,LEFT(IFERROR(INDEX(醫師週班表!$C$5:$T$44,$CU7,CS$57),""),1),""),IF(MID(IFERROR(INDEX(醫師週班表!$C$5:$T$44,$CU7,CS$57),""),2,1)="(",LEFT(IFERROR(INDEX(醫師週班表!$C$5:$T$44,$CU7,CS$57),""),1),IFERROR(INDEX(醫師週班表!$C$5:$T$44,$CU7,CS$57),""))))))) | CU7: =IFERROR(MATCH($A7,醫師週班表!$A$5:$A$44,0),0)
A8: D003 | B8: 王泳泉 | C8: 矯正專科 | E8: =IF(E$59="X","",IF(E$59<>"",E$59,IF(IFERROR(INDEX(醫師週班表!$C$5:$T$44,$CU8,E$57),"")=0,"",IF(MID(IFERROR(INDEX(醫師週班表!$C$5:$T$44,$CU8,E$57),""),2,1)="/",MID(IFERROR(INDEX(醫師週班表!$C$5:$T$44,$CU8,E$57),""),1+E$58*2,1),IF(MID(IFERROR(INDEX(醫師週班表!$C$5:$T$44,$CU8,E$57),""),3,1)="隔",IF(E$58=0,LEFT(IFERROR(INDEX(醫師週班表!$C$5:$T$44,$CU8,E$57),""),1),""),IF(MID(IFERROR(INDEX(醫師週班表!$C$5:$T$44,$CU8,E$57),""),2,1)="(",LEFT(IFERROR(INDEX(醫師週班表!$C$5:$T$44,$CU8,E$57),""),1),IFERROR(INDEX(醫師週班表!$C$5:$T$44,$CU8,E$57),""))))))) | F8: =IF(F$59="X","",IF(F$59<>"",F$59,IF(IFERROR(INDEX(醫師週班表!$C$5:$T$44,$CU8,F$57),"")=0,"",IF(MID(IFERROR(INDEX(醫師週班表!$C$5:$T$44,$CU8,F$57),""),2,1)="/",MID(IFERROR(INDEX(醫師週班表!$C$5:$T$44,$CU8,F$57),""),1+F$58*2,1),IF(MID(IFERROR(INDEX(醫師週班表!$C$5:$T$44,$CU8,F$57),""),3,1)="隔",IF(F$58=0,LEFT(IFERROR(INDEX(醫師週班表!$C$5:$T$44,$CU8,F$57),""),1),""),IF(MID(IFERROR(INDEX(醫師週班表!$C$5:$T$44,$CU8,F$57),""),2,1)="(",LEFT(IFERROR(INDEX(醫師週班表!$C$5:$T$44,$CU8,F$57),""),1),IFERROR(INDEX(醫師週班表!$C$5:$T$44,$CU8,F$57),""))))))) | G8: =IF(G$59="X","",IF(G$59<>"",G$59,IF(IFERROR(INDEX(醫師週班表!$C$5:$T$44,$CU8,G$57),"")=0,"",IF(MID(IFERROR(INDEX(醫師週班表!$C$5:$T$44,$CU8,G$57),""),2,1)="/",MID(IFERROR(INDEX(醫師週班表!$C$5:$T$44,$CU8,G$57),""),1+G$58*2,1),IF(MID(IFERROR(INDEX(醫師週班表!$C$5:$T$44,$CU8,G$57),""),3,1)="隔",IF(G$58=0,LEFT(IFERROR(INDEX(醫師週班表!$C$5:$T$44,$CU8,G$57),""),1),""),IF(MID(IFERROR(INDEX(醫師週班表!$C$5:$T$44,$CU8,G$57),""),2,1)="(",LEFT(IFERROR(INDEX(醫師週班表!$C$5:$T$44,$CU8,G$57),""),1),IFERROR(INDEX(醫師週班表!$C$5:$T$44,$CU8,G$57),""))))))) | H8: =IF(H$59="X","",IF(H$59<>"",H$59,IF(IFERROR(INDEX(醫師週班表!$C$5:$T$44,$CU8,H$57),"")=0,"",IF(MID(IFERROR(INDEX(醫師週班表!$C$5:$T$44,$CU8,H$57),""),2,1)="/",MID(IFERROR(INDEX(醫師週班表!$C$5:$T$44,$CU8,H$57),""),1+H$58*2,1),IF(MID(IFERROR(INDEX(醫師週班表!$C$5:$T$44,$CU8,H$57),""),3,1)="隔",IF(H$58=0,LEFT(IFERROR(INDEX(醫師週班表!$C$5:$T$44,$CU8,H$57),""),1),""),IF(MID(IFERROR(INDEX(醫師週班表!$C$5:$T$44,$CU8,H$57),""),2,1)="(",LEFT(IFERROR(INDEX(醫師週班表!$C$5:$T$44,$CU8,H$57),""),1),IFERROR(INDEX(醫師週班表!$C$5:$T$44,$CU8,H$57),""))))))) | I8: =IF(I$59="X","",IF(I$59<>"",I$59,IF(IFERROR(INDEX(醫師週班表!$C$5:$T$44,$CU8,I$57),"")=0,"",IF(MID(IFERROR(INDEX(醫師週班表!$C$5:$T$44,$CU8,I$57),""),2,1)="/",MID(IFERROR(INDEX(醫師週班表!$C$5:$T$44,$CU8,I$57),""),1+I$58*2,1),IF(MID(IFERROR(INDEX(醫師週班表!$C$5:$T$44,$CU8,I$57),""),3,1)="隔",IF(I$58=0,LEFT(IFERROR(INDEX(醫師週班表!$C$5:$T$44,$CU8,I$57),""),1),""),IF(MID(IFERROR(INDEX(醫師週班表!$C$5:$T$44,$CU8,I$57),""),2,1)="(",LEFT(IFERROR(INDEX(醫師週班表!$C$5:$T$44,$CU8,I$57),""),1),IFERROR(INDEX(醫師週班表!$C$5:$T$44,$CU8,I$57),""))))))) | J8: =IF(J$59="X","",IF(J$59<>"",J$59,IF(IFERROR(INDEX(醫師週班表!$C$5:$T$44,$CU8,J$57),"")=0,"",IF(MID(IFERROR(INDEX(醫師週班表!$C$5:$T$44,$CU8,J$57),""),2,1)="/",MID(IFERROR(INDEX(醫師週班表!$C$5:$T$44,$CU8,J$57),""),1+J$58*2,1),IF(MID(IFERROR(INDEX(醫師週班表!$C$5:$T$44,$CU8,J$57),""),3,1)="隔",IF(J$58=0,LEFT(IFERROR(INDEX(醫師週班表!$C$5:$T$44,$CU8,J$57),""),1),""),IF(MID(IFERROR(INDEX(醫師週班表!$C$5:$T$44,$CU8,J$57),""),2,1)="(",LEFT(IFERROR(INDEX(醫師週班表!$C$5:$T$44,$CU8,J$57),""),1),IFERROR(INDEX(醫師週班表!$C$5:$T$44,$CU8,J$57),""))))))) | K8: =IF(K$59="X","",IF(K$59<>"",K$59,IF(IFERROR(INDEX(醫師週班表!$C$5:$T$44,$CU8,K$57),"")=0,"",IF(MID(IFERROR(INDEX(醫師週班表!$C$5:$T$44,$CU8,K$57),""),2,1)="/",MID(IFERROR(INDEX(醫師週班表!$C$5:$T$44,$CU8,K$57),""),1+K$58*2,1),IF(MID(IFERROR(INDEX(醫師週班表!$C$5:$T$44,$CU8,K$57),""),3,1)="隔",IF(K$58=0,LEFT(IFERROR(INDEX(醫師週班表!$C$5:$T$44,$CU8,K$57),""),1),""),IF(MID(IFERROR(INDEX(醫師週班表!$C$5:$T$44,$CU8,K$57),""),2,1)="(",LEFT(IFERROR(INDEX(醫師週班表!$C$5:$T$44,$CU8,K$57),""),1),IFERROR(INDEX(醫師週班表!$C$5:$T$44,$CU8,K$57),""))))))) | L8: =IF(L$59="X","",IF(L$59<>"",L$59,IF(IFERROR(INDEX(醫師週班表!$C$5:$T$44,$CU8,L$57),"")=0,"",IF(MID(IFERROR(INDEX(醫師週班表!$C$5:$T$44,$CU8,L$57),""),2,1)="/",MID(IFERROR(INDEX(醫師週班表!$C$5:$T$44,$CU8,L$57),""),1+L$58*2,1),IF(MID(IFERROR(INDEX(醫師週班表!$C$5:$T$44,$CU8,L$57),""),3,1)="隔",IF(L$58=0,LEFT(IFERROR(INDEX(醫師週班表!$C$5:$T$44,$CU8,L$57),""),1),""),IF(MID(IFERROR(INDEX(醫師週班表!$C$5:$T$44,$CU8,L$57),""),2,1)="(",LEFT(IFERROR(INDEX(醫師週班表!$C$5:$T$44,$CU8,L$57),""),1),IFERROR(INDEX(醫師週班表!$C$5:$T$44,$CU8,L$57),""))))))) | ... CS8: =IF(CS$59="X","",IF(CS$59<>"",CS$59,IF(IFERROR(INDEX(醫師週班表!$C$5:$T$44,$CU8,CS$57),"")=0,"",IF(MID(IFERROR(INDEX(醫師週班表!$C$5:$T$44,$CU8,CS$57),""),2,1)="/",MID(IFERROR(INDEX(醫師週班表!$C$5:$T$44,$CU8,CS$57),""),1+CS$58*2,1),IF(MID(IFERROR(INDEX(醫師週班表!$C$5:$T$44,$CU8,CS$57),""),3,1)="隔",IF(CS$58=0,LEFT(IFERROR(INDEX(醫師週班表!$C$5:$T$44,$CU8,CS$57),""),1),""),IF(MID(IFERROR(INDEX(醫師週班表!$C$5:$T$44,$CU8,CS$57),""),2,1)="(",LEFT(IFERROR(INDEX(醫師週班表!$C$5:$T$44,$CU8,CS$57),""),1),IFERROR(INDEX(醫師週班表!$C$5:$T$44,$CU8,CS$57),""))))))) | CU8: =IFERROR(MATCH($A8,醫師週班表!$A$5:$A$44,0),0)
A9: D004 | B9: 劉玠旻 | C9: 兒童專科 | E9: =IF(E$59="X","",IF(E$59<>"",E$59,IF(IFERROR(INDEX(醫師週班表!$C$5:$T$44,$CU9,E$57),"")=0,"",IF(MID(IFERROR(INDEX(醫師週班表!$C$5:$T$44,$CU9,E$57),""),2,1)="/",MID(IFERROR(INDEX(醫師週班表!$C$5:$T$44,$CU9,E$57),""),1+E$58*2,1),IF(MID(IFERROR(INDEX(醫師週班表!$C$5:$T$44,$CU9,E$57),""),3,1)="隔",IF(E$58=0,LEFT(IFERROR(INDEX(醫師週班表!$C$5:$T$44,$CU9,E$57),""),1),""),IF(MID(IFERROR(INDEX(醫師週班表!$C$5:$T$44,$CU9,E$57),""),2,1)="(",LEFT(IFERROR(INDEX(醫師週班表!$C$5:$T$44,$CU9,E$57),""),1),IFERROR(INDEX(醫師週班表!$C$5:$T$44,$CU9,E$57),""))))))) | F9: =IF(F$59="X","",IF(F$59<>"",F$59,IF(IFERROR(INDEX(醫師週班表!$C$5:$T$44,$CU9,F$57),"")=0,"",IF(MID(IFERROR(INDEX(醫師週班表!$C$5:$T$44,$CU9,F$57),""),2,1)="/",MID(IFERROR(INDEX(醫師週班表!$C$5:$T$44,$CU9,F$57),""),1+F$58*2,1),IF(MID(IFERROR(INDEX(醫師週班表!$C$5:$T$44,$CU9,F$57),""),3,1)="隔",IF(F$58=0,LEFT(IFERROR(INDEX(醫師週班表!$C$5:$T$44,$CU9,F$57),""),1),""),IF(MID(IFERROR(INDEX(醫師週班表!$C$5:$T$44,$CU9,F$57),""),2,1)="(",LEFT(IFERROR(INDEX(醫師週班表!$C$5:$T$44,$CU9,F$57),""),1),IFERROR(INDEX(醫師週班表!$C$5:$T$44,$CU9,F$57),""))))))) | G9: =IF(G$59="X","",IF(G$59<>"",G$59,IF(IFERROR(INDEX(醫師週班表!$C$5:$T$44,$CU9,G$57),"")=0,"",IF(MID(IFERROR(INDEX(醫師週班表!$C$5:$T$44,$CU9,G$57),""),2,1)="/",MID(IFERROR(INDEX(醫師週班表!$C$5:$T$44,$CU9,G$57),""),1+G$58*2,1),IF(MID(IFERROR(INDEX(醫師週班表!$C$5:$T$44,$CU9,G$57),""),3,1)="隔",IF(G$58=0,LEFT(IFERROR(INDEX(醫師週班表!$C$5:$T$44,$CU9,G$57),""),1),""),IF(MID(IFERROR(INDEX(醫師週班表!$C$5:$T$44,$CU9,G$57),""),2,1)="(",LEFT(IFERROR(INDEX(醫師週班表!$C$5:$T$44,$CU9,G$57),""),1),IFERROR(INDEX(醫師週班表!$C$5:$T$44,$CU9,G$57),""))))))) | H9: =IF(H$59="X","",IF(H$59<>"",H$59,IF(IFERROR(INDEX(醫師週班表!$C$5:$T$44,$CU9,H$57),"")=0,"",IF(MID(IFERROR(INDEX(醫師週班表!$C$5:$T$44,$CU9,H$57),""),2,1)="/",MID(IFERROR(INDEX(醫師週班表!$C$5:$T$44,$CU9,H$57),""),1+H$58*2,1),IF(MID(IFERROR(INDEX(醫師週班表!$C$5:$T$44,$CU9,H$57),""),3,1)="隔",IF(H$58=0,LEFT(IFERROR(INDEX(醫師週班表!$C$5:$T$44,$CU9,H$57),""),1),""),IF(MID(IFERROR(INDEX(醫師週班表!$C$5:$T$44,$CU9,H$57),""),2,1)="(",LEFT(IFERROR(INDEX(醫師週班表!$C$5:$T$44,$CU9,H$57),""),1),IFERROR(INDEX(醫師週班表!$C$5:$T$44,$CU9,H$57),""))))))) | I9: =IF(I$59="X","",IF(I$59<>"",I$59,IF(IFERROR(INDEX(醫師週班表!$C$5:$T$44,$CU9,I$57),"")=0,"",IF(MID(IFERROR(INDEX(醫師週班表!$C$5:$T$44,$CU9,I$57),""),2,1)="/",MID(IFERROR(INDEX(醫師週班表!$C$5:$T$44,$CU9,I$57),""),1+I$58*2,1),IF(MID(IFERROR(INDEX(醫師週班表!$C$5:$T$44,$CU9,I$57),""),3,1)="隔",IF(I$58=0,LEFT(IFERROR(INDEX(醫師週班表!$C$5:$T$44,$CU9,I$57),""),1),""),IF(MID(IFERROR(INDEX(醫師週班表!$C$5:$T$44,$CU9,I$57),""),2,1)="(",LEFT(IFERROR(INDEX(醫師週班表!$C$5:$T$44,$CU9,I$57),""),1),IFERROR(INDEX(醫師週班表!$C$5:$T$44,$CU9,I$57),""))))))) | J9: =IF(J$59="X","",IF(J$59<>"",J$59,IF(IFERROR(INDEX(醫師週班表!$C$5:$T$44,$CU9,J$57),"")=0,"",IF(MID(IFERROR(INDEX(醫師週班表!$C$5:$T$44,$CU9,J$57),""),2,1)="/",MID(IFERROR(INDEX(醫師週班表!$C$5:$T$44,$CU9,J$57),""),1+J$58*2,1),IF(MID(IFERROR(INDEX(醫師週班表!$C$5:$T$44,$CU9,J$57),""),3,1)="隔",IF(J$58=0,LEFT(IFERROR(INDEX(醫師週班表!$C$5:$T$44,$CU9,J$57),""),1),""),IF(MID(IFERROR(INDEX(醫師週班表!$C$5:$T$44,$CU9,J$57),""),2,1)="(",LEFT(IFERROR(INDEX(醫師週班表!$C$5:$T$44,$CU9,J$57),""),1),IFERROR(INDEX(醫師週班表!$C$5:$T$44,$CU9,J$57),""))))))) | K9: =IF(K$59="X","",IF(K$59<>"",K$59,IF(IFERROR(INDEX(醫師週班表!$C$5:$T$44,$CU9,K$57),"")=0,"",IF(MID(IFERROR(INDEX(醫師週班表!$C$5:$T$44,$CU9,K$57),""),2,1)="/",MID(IFERROR(INDEX(醫師週班表!$C$5:$T$44,$CU9,K$57),""),1+K$58*2,1),IF(MID(IFERROR(INDEX(醫師週班表!$C$5:$T$44,$CU9,K$57),""),3,1)="隔",IF(K$58=0,LEFT(IFERROR(INDEX(醫師週班表!$C$5:$T$44,$CU9,K$57),""),1),""),IF(MID(IFERROR(INDEX(醫師週班表!$C$5:$T$44,$CU9,K$57),""),2,1)="(",LEFT(IFERROR(INDEX(醫師週班表!$C$5:$T$44,$CU9,K$57),""),1),IFERROR(INDEX(醫師週班表!$C$5:$T$44,$CU9,K$57),""))))))) | L9: =IF(L$59="X","",IF(L$59<>"",L$59,IF(IFERROR(INDEX(醫師週班表!$C$5:$T$44,$CU9,L$57),"")=0,"",IF(MID(IFERROR(INDEX(醫師週班表!$C$5:$T$44,$CU9,L$57),""),2,1)="/",MID(IFERROR(INDEX(醫師週班表!$C$5:$T$44,$CU9,L$57),""),1+L$58*2,1),IF(MID(IFERROR(INDEX(醫師週班表!$C$5:$T$44,$CU9,L$57),""),3,1)="隔",IF(L$58=0,LEFT(IFERROR(INDEX(醫師週班表!$C$5:$T$44,$CU9,L$57),""),1),""),IF(MID(IFERROR(INDEX(醫師週班表!$C$5:$T$44,$CU9,L$57),""),2,1)="(",LEFT(IFERROR(INDEX(醫師週班表!$C$5:$T$44,$CU9,L$57),""),1),IFERROR(INDEX(醫師週班表!$C$5:$T$44,$CU9,L$57),""))))))) | ... CS9: =IF(CS$59="X","",IF(CS$59<>"",CS$59,IF(IFERROR(INDEX(醫師週班表!$C$5:$T$44,$CU9,CS$57),"")=0,"",IF(MID(IFERROR(INDEX(醫師週班表!$C$5:$T$44,$CU9,CS$57),""),2,1)="/",MID(IFERROR(INDEX(醫師週班表!$C$5:$T$44,$CU9,CS$57),""),1+CS$58*2,1),IF(MID(IFERROR(INDEX(醫師週班表!$C$5:$T$44,$CU9,CS$57),""),3,1)="隔",IF(CS$58=0,LEFT(IFERROR(INDEX(醫師週班表!$C$5:$T$44,$CU9,CS$57),""),1),""),IF(MID(IFERROR(INDEX(醫師週班表!$C$5:$T$44,$CU9,CS$57),""),2,1)="(",LEFT(IFERROR(INDEX(醫師週班表!$C$5:$T$44,$CU9,CS$57),""),1),IFERROR(INDEX(醫師週班表!$C$5:$T$44,$CU9,CS$57),""))))))) | CU9: =IFERROR(MATCH($A9,醫師週班表!$A$5:$A$44,0),0)
A10: D005 | B10: 陳志僑 | C10: 口外專科 | E10: =IF(E$59="X","",IF(E$59<>"",E$59,IF(IFERROR(INDEX(醫師週班表!$C$5:$T$44,$CU10,E$57),"")=0,"",IF(MID(IFERROR(INDEX(醫師週班表!$C$5:$T$44,$CU10,E$57),""),2,1)="/",MID(IFERROR(INDEX(醫師週班表!$C$5:$T$44,$CU10,E$57),""),1+E$58*2,1),IF(MID(IFERROR(INDEX(醫師週班表!$C$5:$T$44,$CU10,E$57),""),3,1)="隔",IF(E$58=0,LEFT(IFERROR(INDEX(醫師週班表!$C$5:$T$44,$CU10,E$57),""),1),""),IF(MID(IFERROR(INDEX(醫師週班表!$C$5:$T$44,$CU10,E$57),""),2,1)="(",LEFT(IFERROR(INDEX(醫師週班表!$C$5:$T$44,$CU10,E$57),""),1),IFERROR(INDEX(醫師週班表!$C$5:$T$44,$CU10,E$57),""))))))) | F10: =IF(F$59="X","",IF(F$59<>"",F$59,IF(IFERROR(INDEX(醫師週班表!$C$5:$T$44,$CU10,F$57),"")=0,"",IF(MID(IFERROR(INDEX(醫師週班表!$C$5:$T$44,$CU10,F$57),""),2,1)="/",MID(IFERROR(INDEX(醫師週班表!$C$5:$T$44,$CU10,F$57),""),1+F$58*2,1),IF(MID(IFERROR(INDEX(醫師週班表!$C$5:$T$44,$CU10,F$57),""),3,1)="隔",IF(F$58=0,LEFT(IFERROR(INDEX(醫師週班表!$C$5:$T$44,$CU10,F$57),""),1),""),IF(MID(IFERROR(INDEX(醫師週班表!$C$5:$T$44,$CU10,F$57),""),2,1)="(",LEFT(IFERROR(INDEX(醫師週班表!$C$5:$T$44,$CU10,F$57),""),1),IFERROR(INDEX(醫師週班表!$C$5:$T$44,$CU10,F$57),""))))))) | G10: =IF(G$59="X","",IF(G$59<>"",G$59,IF(IFERROR(INDEX(醫師週班表!$C$5:$T$44,$CU10,G$57),"")=0,"",IF(MID(IFERROR(INDEX(醫師週班表!$C$5:$T$44,$CU10,G$57),""),2,1)="/",MID(IFERROR(INDEX(醫師週班表!$C$5:$T$44,$CU10,G$57),""),1+G$58*2,1),IF(MID(IFERROR(INDEX(醫師週班表!$C$5:$T$44,$CU10,G$57),""),3,1)="隔",IF(G$58=0,LEFT(IFERROR(INDEX(醫師週班表!$C$5:$T$44,$CU10,G$57),""),1),""),IF(MID(IFERROR(INDEX(醫師週班表!$C$5:$T$44,$CU10,G$57),""),2,1)="(",LEFT(IFERROR(INDEX(醫師週班表!$C$5:$T$44,$CU10,G$57),""),1),IFERROR(INDEX(醫師週班表!$C$5:$T$44,$CU10,G$57),""))))))) | H10: =IF(H$59="X","",IF(H$59<>"",H$59,IF(IFERROR(INDEX(醫師週班表!$C$5:$T$44,$CU10,H$57),"")=0,"",IF(MID(IFERROR(INDEX(醫師週班表!$C$5:$T$44,$CU10,H$57),""),2,1)="/",MID(IFERROR(INDEX(醫師週班表!$C$5:$T$44,$CU10,H$57),""),1+H$58*2,1),IF(MID(IFERROR(INDEX(醫師週班表!$C$5:$T$44,$CU10,H$57),""),3,1)="隔",IF(H$58=0,LEFT(IFERROR(INDEX(醫師週班表!$C$5:$T$44,$CU10,H$57),""),1),""),IF(MID(IFERROR(INDEX(醫師週班表!$C$5:$T$44,$CU10,H$57),""),2,1)="(",LEFT(IFERROR(INDEX(醫師週班表!$C$5:$T$44,$CU10,H$57),""),1),IFERROR(INDEX(醫師週班表!$C$5:$T$44,$CU10,H$57),""))))))) | I10: =IF(I$59="X","",IF(I$59<>"",I$59,IF(IFERROR(INDEX(醫師週班表!$C$5:$T$44,$CU10,I$57),"")=0,"",IF(MID(IFERROR(INDEX(醫師週班表!$C$5:$T$44,$CU10,I$57),""),2,1)="/",MID(IFERROR(INDEX(醫師週班表!$C$5:$T$44,$CU10,I$57),""),1+I$58*2,1),IF(MID(IFERROR(INDEX(醫師週班表!$C$5:$T$44,$CU10,I$57),""),3,1)="隔",IF(I$58=0,LEFT(IFERROR(INDEX(醫師週班表!$C$5:$T$44,$CU10,I$57),""),1),""),IF(MID(IFERROR(INDEX(醫師週班表!$C$5:$T$44,$CU10,I$57),""),2,1)="(",LEFT(IFERROR(INDEX(醫師週班表!$C$5:$T$44,$CU10,I$57),""),1),IFERROR(INDEX(醫師週班表!$C$5:$T$44,$CU10,I$57),""))))))) | J10: =IF(J$59="X","",IF(J$59<>"",J$59,IF(IFERROR(INDEX(醫師週班表!$C$5:$T$44,$CU10,J$57),"")=0,"",IF(MID(IFERROR(INDEX(醫師週班表!$C$5:$T$44,$CU10,J$57),""),2,1)="/",MID(IFERROR(INDEX(醫師週班表!$C$5:$T$44,$CU10,J$57),""),1+J$58*2,1),IF(MID(IFERROR(INDEX(醫師週班表!$C$5:$T$44,$CU10,J$57),""),3,1)="隔",IF(J$58=0,LEFT(IFERROR(INDEX(醫師週班表!$C$5:$T$44,$CU10,J$57),""),1),""),IF(MID(IFERROR(INDEX(醫師週班表!$C$5:$T$44,$CU10,J$57),""),2,1)="(",LEFT(IFERROR(INDEX(醫師週班表!$C$5:$T$44,$CU10,J$57),""),1),IFERROR(INDEX(醫師週班表!$C$5:$T$44,$CU10,J$57),""))))))) | K10: =IF(K$59="X","",IF(K$59<>"",K$59,IF(IFERROR(INDEX(醫師週班表!$C$5:$T$44,$CU10,K$57),"")=0,"",IF(MID(IFERROR(INDEX(醫師週班表!$C$5:$T$44,$CU10,K$57),""),2,1)="/",MID(IFERROR(INDEX(醫師週班表!$C$5:$T$44,$CU10,K$57),""),1+K$58*2,1),IF(MID(IFERROR(INDEX(醫師週班表!$C$5:$T$44,$CU10,K$57),""),3,1)="隔",IF(K$58=0,LEFT(IFERROR(INDEX(醫師週班表!$C$5:$T$44,$CU10,K$57),""),1),""),IF(MID(IFERROR(INDEX(醫師週班表!$C$5:$T$44,$CU10,K$57),""),2,1)="(",LEFT(IFERROR(INDEX(醫師週班表!$C$5:$T$44,$CU10,K$57),""),1),IFERROR(INDEX(醫師週班表!$C$5:$T$44,$CU10,K$57),""))))))) | L10: =IF(L$59="X","",IF(L$59<>"",L$59,IF(IFERROR(INDEX(醫師週班表!$C$5:$T$44,$CU10,L$57),"")=0,"",IF(MID(IFERROR(INDEX(醫師週班表!$C$5:$T$44,$CU10,L$57),""),2,1)="/",MID(IFERROR(INDEX(醫師週班表!$C$5:$T$44,$CU10,L$57),""),1+L$58*2,1),IF(MID(IFERROR(INDEX(醫師週班表!$C$5:$T$44,$CU10,L$57),""),3,1)="隔",IF(L$58=0,LEFT(IFERROR(INDEX(醫師週班表!$C$5:$T$44,$CU10,L$57),""),1),""),IF(MID(IFERROR(INDEX(醫師週班表!$C$5:$T$44,$CU10,L$57),""),2,1)="(",LEFT(IFERROR(INDEX(醫師週班表!$C$5:$T$44,$CU10,L$57),""),1),IFERROR(INDEX(醫師週班表!$C$5:$T$44,$CU10,L$57),""))))))) | ... CS10: =IF(CS$59="X","",IF(CS$59<>"",CS$59,IF(IFERROR(INDEX(醫師週班表!$C$5:$T$44,$CU10,CS$57),"")=0,"",IF(MID(IFERROR(INDEX(醫師週班表!$C$5:$T$44,$CU10,CS$57),""),2,1)="/",MID(IFERROR(INDEX(醫師週班表!$C$5:$T$44,$CU10,CS$57),""),1+CS$58*2,1),IF(MID(IFERROR(INDEX(醫師週班表!$C$5:$T$44,$CU10,CS$57),""),3,1)="隔",IF(CS$58=0,LEFT(IFERROR(INDEX(醫師週班表!$C$5:$T$44,$CU10,CS$57),""),1),""),IF(MID(IFERROR(INDEX(醫師週班表!$C$5:$T$44,$CU10,CS$57),""),2,1)="(",LEFT(IFERROR(INDEX(醫師週班表!$C$5:$T$44,$CU10,CS$57),""),1),IFERROR(INDEX(醫師週班表!$C$5:$T$44,$CU10,CS$57),""))))))) | CU10: =IFERROR(MATCH($A10,醫師週班表!$A$5:$A$44,0),0)
A11: D006 | B11: 黃榆鈞 | C11: 矯正專科 | E11: =IF(E$59="X","",IF(E$59<>"",E$59,IF(IFERROR(INDEX(醫師週班表!$C$5:$T$44,$CU11,E$57),"")=0,"",IF(MID(IFERROR(INDEX(醫師週班表!$C$5:$T$44,$CU11,E$57),""),2,1)="/",MID(IFERROR(INDEX(醫師週班表!$C$5:$T$44,$CU11,E$57),""),1+E$58*2,1),IF(MID(IFERROR(INDEX(醫師週班表!$C$5:$T$44,$CU11,E$57),""),3,1)="隔",IF(E$58=0,LEFT(IFERROR(INDEX(醫師週班表!$C$5:$T$44,$CU11,E$57),""),1),""),IF(MID(IFERROR(INDEX(醫師週班表!$C$5:$T$44,$CU11,E$57),""),2,1)="(",LEFT(IFERROR(INDEX(醫師週班表!$C$5:$T$44,$CU11,E$57),""),1),IFERROR(INDEX(醫師週班表!$C$5:$T$44,$CU11,E$57),""))))))) | F11: =IF(F$59="X","",IF(F$59<>"",F$59,IF(IFERROR(INDEX(醫師週班表!$C$5:$T$44,$CU11,F$57),"")=0,"",IF(MID(IFERROR(INDEX(醫師週班表!$C$5:$T$44,$CU11,F$57),""),2,1)="/",MID(IFERROR(INDEX(醫師週班表!$C$5:$T$44,$CU11,F$57),""),1+F$58*2,1),IF(MID(IFERROR(INDEX(醫師週班表!$C$5:$T$44,$CU11,F$57),""),3,1)="隔",IF(F$58=0,LEFT(IFERROR(INDEX(醫師週班表!$C$5:$T$44,$CU11,F$57),""),1),""),IF(MID(IFERROR(INDEX(醫師週班表!$C$5:$T$44,$CU11,F$57),""),2,1)="(",LEFT(IFERROR(INDEX(醫師週班表!$C$5:$T$44,$CU11,F$57),""),1),IFERROR(INDEX(醫師週班表!$C$5:$T$44,$CU11,F$57),""))))))) | G11: =IF(G$59="X","",IF(G$59<>"",G$59,IF(IFERROR(INDEX(醫師週班表!$C$5:$T$44,$CU11,G$57),"")=0,"",IF(MID(IFERROR(INDEX(醫師週班表!$C$5:$T$44,$CU11,G$57),""),2,1)="/",MID(IFERROR(INDEX(醫師週班表!$C$5:$T$44,$CU11,G$57),""),1+G$58*2,1),IF(MID(IFERROR(INDEX(醫師週班表!$C$5:$T$44,$CU11,G$57),""),3,1)="隔",IF(G$58=0,LEFT(IFERROR(INDEX(醫師週班表!$C$5:$T$44,$CU11,G$57),""),1),""),IF(MID(IFERROR(INDEX(醫師週班表!$C$5:$T$44,$CU11,G$57),""),2,1)="(",LEFT(IFERROR(INDEX(醫師週班表!$C$5:$T$44,$CU11,G$57),""),1),IFERROR(INDEX(醫師週班表!$C$5:$T$44,$CU11,G$57),""))))))) | H11: =IF(H$59="X","",IF(H$59<>"",H$59,IF(IFERROR(INDEX(醫師週班表!$C$5:$T$44,$CU11,H$57),"")=0,"",IF(MID(IFERROR(INDEX(醫師週班表!$C$5:$T$44,$CU11,H$57),""),2,1)="/",MID(IFERROR(INDEX(醫師週班表!$C$5:$T$44,$CU11,H$57),""),1+H$58*2,1),IF(MID(IFERROR(INDEX(醫師週班表!$C$5:$T$44,$CU11,H$57),""),3,1)="隔",IF(H$58=0,LEFT(IFERROR(INDEX(醫師週班表!$C$5:$T$44,$CU11,H$57),""),1),""),IF(MID(IFERROR(INDEX(醫師週班表!$C$5:$T$44,$CU11,H$57),""),2,1)="(",LEFT(IFERROR(INDEX(醫師週班表!$C$5:$T$44,$CU11,H$57),""),1),IFERROR(INDEX(醫師週班表!$C$5:$T$44,$CU11,H$57),""))))))) | I11: =IF(I$59="X","",IF(I$59<>"",I$59,IF(IFERROR(INDEX(醫師週班表!$C$5:$T$44,$CU11,I$57),"")=0,"",IF(MID(IFERROR(INDEX(醫師週班表!$C$5:$T$44,$CU11,I$57),""),2,1)="/",MID(IFERROR(INDEX(醫師週班表!$C$5:$T$44,$CU11,I$57),""),1+I$58*2,1),IF(MID(IFERROR(INDEX(醫師週班表!$C$5:$T$44,$CU11,I$57),""),3,1)="隔",IF(I$58=0,LEFT(IFERROR(INDEX(醫師週班表!$C$5:$T$44,$CU11,I$57),""),1),""),IF(MID(IFERROR(INDEX(醫師週班表!$C$5:$T$44,$CU11,I$57),""),2,1)="(",LEFT(IFERROR(INDEX(醫師週班表!$C$5:$T$44,$CU11,I$57),""),1),IFERROR(INDEX(醫師週班表!$C$5:$T$44,$CU11,I$57),""))))))) | J11: =IF(J$59="X","",IF(J$59<>"",J$59,IF(IFERROR(INDEX(醫師週班表!$C$5:$T$44,$CU11,J$57),"")=0,"",IF(MID(IFERROR(INDEX(醫師週班表!$C$5:$T$44,$CU11,J$57),""),2,1)="/",MID(IFERROR(INDEX(醫師週班表!$C$5:$T$44,$CU11,J$57),""),1+J$58*2,1),IF(MID(IFERROR(INDEX(醫師週班表!$C$5:$T$44,$CU11,J$57),""),3,1)="隔",IF(J$58=0,LEFT(IFERROR(INDEX(醫師週班表!$C$5:$T$44,$CU11,J$57),""),1),""),IF(MID(IFERROR(INDEX(醫師週班表!$C$5:$T$44,$CU11,J$57),""),2,1)="(",LEFT(IFERROR(INDEX(醫師週班表!$C$5:$T$44,$CU11,J$57),""),1),IFERROR(INDEX(醫師週班表!$C$5:$T$44,$CU11,J$57),""))))))) | K11: =IF(K$59="X","",IF(K$59<>"",K$59,IF(IFERROR(INDEX(醫師週班表!$C$5:$T$44,$CU11,K$57),"")=0,"",IF(MID(IFERROR(INDEX(醫師週班表!$C$5:$T$44,$CU11,K$57),""),2,1)="/",MID(IFERROR(INDEX(醫師週班表!$C$5:$T$44,$CU11,K$57),""),1+K$58*2,1),IF(MID(IFERROR(INDEX(醫師週班表!$C$5:$T$44,$CU11,K$57),""),3,1)="隔",IF(K$58=0,LEFT(IFERROR(INDEX(醫師週班表!$C$5:$T$44,$CU11,K$57),""),1),""),IF(MID(IFERROR(INDEX(醫師週班表!$C$5:$T$44,$CU11,K$57),""),2,1)="(",LEFT(IFERROR(INDEX(醫師週班表!$C$5:$T$44,$CU11,K$57),""),1),IFERROR(INDEX(醫師週班表!$C$5:$T$44,$CU11,K$57),""))))))) | L11: =IF(L$59="X","",IF(L$59<>"",L$59,IF(IFERROR(INDEX(醫師週班表!$C$5:$T$44,$CU11,L$57),"")=0,"",IF(MID(IFERROR(INDEX(醫師週班表!$C$5:$T$44,$CU11,L$57),""),2,1)="/",MID(IFERROR(INDEX(醫師週班表!$C$5:$T$44,$CU11,L$57),""),1+L$58*2,1),IF(MID(IFERROR(INDEX(醫師週班表!$C$5:$T$44,$CU11,L$57),""),3,1)="隔",IF(L$58=0,LEFT(IFERROR(INDEX(醫師週班表!$C$5:$T$44,$CU11,L$57),""),1),""),IF(MID(IFERROR(INDEX(醫師週班表!$C$5:$T$44,$CU11,L$57),""),2,1)="(",LEFT(IFERROR(INDEX(醫師週班表!$C$5:$T$44,$CU11,L$57),""),1),IFERROR(INDEX(醫師週班表!$C$5:$T$44,$CU11,L$57),""))))))) | ... CS11: =IF(CS$59="X","",IF(CS$59<>"",CS$59,IF(IFERROR(INDEX(醫師週班表!$C$5:$T$44,$CU11,CS$57),"")=0,"",IF(MID(IFERROR(INDEX(醫師週班表!$C$5:$T$44,$CU11,CS$57),""),2,1)="/",MID(IFERROR(INDEX(醫師週班表!$C$5:$T$44,$CU11,CS$57),""),1+CS$58*2,1),IF(MID(IFERROR(INDEX(醫師週班表!$C$5:$T$44,$CU11,CS$57),""),3,1)="隔",IF(CS$58=0,LEFT(IFERROR(INDEX(醫師週班表!$C$5:$T$44,$CU11,CS$57),""),1),""),IF(MID(IFERROR(INDEX(醫師週班表!$C$5:$T$44,$CU11,CS$57),""),2,1)="(",LEFT(IFERROR(INDEX(醫師週班表!$C$5:$T$44,$CU11,CS$57),""),1),IFERROR(INDEX(醫師週班表!$C$5:$T$44,$CU11,CS$57),""))))))) | CU11: =IFERROR(MATCH($A11,醫師週班表!$A$5:$A$44,0),0)
A12: D007 | B12: 温翊君 | C12: 根管治療專科 | E12: =IF(E$59="X","",IF(E$59<>"",E$59,IF(IFERROR(INDEX(醫師週班表!$C$5:$T$44,$CU12,E$57),"")=0,"",IF(MID(IFERROR(INDEX(醫師週班表!$C$5:$T$44,$CU12,E$57),""),2,1)="/",MID(IFERROR(INDEX(醫師週班表!$C$5:$T$44,$CU12,E$57),""),1+E$58*2,1),IF(MID(IFERROR(INDEX(醫師週班表!$C$5:$T$44,$CU12,E$57),""),3,1)="隔",IF(E$58=0,LEFT(IFERROR(INDEX(醫師週班表!$C$5:$T$44,$CU12,E$57),""),1),""),IF(MID(IFERROR(INDEX(醫師週班表!$C$5:$T$44,$CU12,E$57),""),2,1)="(",LEFT(IFERROR(INDEX(醫師週班表!$C$5:$T$44,$CU12,E$57),""),1),IFERROR(INDEX(醫師週班表!$C$5:$T$44,$CU12,E$57),""))))))) | F12: =IF(F$59="X","",IF(F$59<>"",F$59,IF(IFERROR(INDEX(醫師週班表!$C$5:$T$44,$CU12,F$57),"")=0,"",IF(MID(IFERROR(INDEX(醫師週班表!$C$5:$T$44,$CU12,F$57),""),2,1)="/",MID(IFERROR(INDEX(醫師週班表!$C$5:$T$44,$CU12,F$57),""),1+F$58*2,1),IF(MID(IFERROR(INDEX(醫師週班表!$C$5:$T$44,$CU12,F$57),""),3,1)="隔",IF(F$58=0,LEFT(IFERROR(INDEX(醫師週班表!$C$5:$T$44,$CU12,F$57),""),1),""),IF(MID(IFERROR(INDEX(醫師週班表!$C$5:$T$44,$CU12,F$57),""),2,1)="(",LEFT(IFERROR(INDEX(醫師週班表!$C$5:$T$44,$CU12,F$57),""),1),IFERROR(INDEX(醫師週班表!$C$5:$T$44,$CU12,F$57),""))))))) | G12: =IF(G$59="X","",IF(G$59<>"",G$59,IF(IFERROR(INDEX(醫師週班表!$C$5:$T$44,$CU12,G$57),"")=0,"",IF(MID(IFERROR(INDEX(醫師週班表!$C$5:$T$44,$CU12,G$57),""),2,1)="/",MID(IFERROR(INDEX(醫師週班表!$C$5:$T$44,$CU12,G$57),""),1+G$58*2,1),IF(MID(IFERROR(INDEX(醫師週班表!$C$5:$T$44,$CU12,G$57),""),3,1)="隔",IF(G$58=0,LEFT(IFERROR(INDEX(醫師週班表!$C$5:$T$44,$CU12,G$57),""),1),""),IF(MID(IFERROR(INDEX(醫師週班表!$C$5:$T$44,$CU12,G$57),""),2,1)="(",LEFT(IFERROR(INDEX(醫師週班表!$C$5:$T$44,$CU12,G$57),""),1),IFERROR(INDEX(醫師週班表!$C$5:$T$44,$CU12,G$57),""))))))) | H12: =IF(H$59="X","",IF(H$59<>"",H$59,IF(IFERROR(INDEX(醫師週班表!$C$5:$T$44,$CU12,H$57),"")=0,"",IF(MID(IFERROR(INDEX(醫師週班表!$C$5:$T$44,$CU12,H$57),""),2,1)="/",MID(IFERROR(INDEX(醫師週班表!$C$5:$T$44,$CU12,H$57),""),1+H$58*2,1),IF(MID(IFERROR(INDEX(醫師週班表!$C$5:$T$44,$CU12,H$57),""),3,1)="隔",IF(H$58=0,LEFT(IFERROR(INDEX(醫師週班表!$C$5:$T$44,$CU12,H$57),""),1),""),IF(MID(IFERROR(INDEX(醫師週班表!$C$5:$T$44,$CU12,H$57),""),2,1)="(",LEFT(IFERROR(INDEX(醫師週班表!$C$5:$T$44,$CU12,H$57),""),1),IFERROR(INDEX(醫師週班表!$C$5:$T$44,$CU12,H$57),""))))))) | I12: =IF(I$59="X","",IF(I$59<>"",I$59,IF(IFERROR(INDEX(醫師週班表!$C$5:$T$44,$CU12,I$57),"")=0,"",IF(MID(IFERROR(INDEX(醫師週班表!$C$5:$T$44,$CU12,I$57),""),2,1)="/",MID(IFERROR(INDEX(醫師週班表!$C$5:$T$44,$CU12,I$57),""),1+I$58*2,1),IF(MID(IFERROR(INDEX(醫師週班表!$C$5:$T$44,$CU12,I$57),""),3,1)="隔",IF(I$58=0,LEFT(IFERROR(INDEX(醫師週班表!$C$5:$T$44,$CU12,I$57),""),1),""),IF(MID(IFERROR(INDEX(醫師週班表!$C$5:$T$44,$CU12,I$57),""),2,1)="(",LEFT(IFERROR(INDEX(醫師週班表!$C$5:$T$44,$CU12,I$57),""),1),IFERROR(INDEX(醫師週班表!$C$5:$T$44,$CU12,I$57),""))))))) | J12: =IF(J$59="X","",IF(J$59<>"",J$59,IF(IFERROR(INDEX(醫師週班表!$C$5:$T$44,$CU12,J$57),"")=0,"",IF(MID(IFERROR(INDEX(醫師週班表!$C$5:$T$44,$CU12,J$57),""),2,1)="/",MID(IFERROR(INDEX(醫師週班表!$C$5:$T$44,$CU12,J$57),""),1+J$58*2,1),IF(MID(IFERROR(INDEX(醫師週班表!$C$5:$T$44,$CU12,J$57),""),3,1)="隔",IF(J$58=0,LEFT(IFERROR(INDEX(醫師週班表!$C$5:$T$44,$CU12,J$57),""),1),""),IF(MID(IFERROR(INDEX(醫師週班表!$C$5:$T$44,$CU12,J$57),""),2,1)="(",LEFT(IFERROR(INDEX(醫師週班表!$C$5:$T$44,$CU12,J$57),""),1),IFERROR(INDEX(醫師週班表!$C$5:$T$44,$CU12,J$57),""))))))) | K12: =IF(K$59="X","",IF(K$59<>"",K$59,IF(IFERROR(INDEX(醫師週班表!$C$5:$T$44,$CU12,K$57),"")=0,"",IF(MID(IFERROR(INDEX(醫師週班表!$C$5:$T$44,$CU12,K$57),""),2,1)="/",MID(IFERROR(INDEX(醫師週班表!$C$5:$T$44,$CU12,K$57),""),1+K$58*2,1),IF(MID(IFERROR(INDEX(醫師週班表!$C$5:$T$44,$CU12,K$57),""),3,1)="隔",IF(K$58=0,LEFT(IFERROR(INDEX(醫師週班表!$C$5:$T$44,$CU12,K$57),""),1),""),IF(MID(IFERROR(INDEX(醫師週班表!$C$5:$T$44,$CU12,K$57),""),2,1)="(",LEFT(IFERROR(INDEX(醫師週班表!$C$5:$T$44,$CU12,K$57),""),1),IFERROR(INDEX(醫師週班表!$C$5:$T$44,$CU12,K$57),""))))))) | L12: =IF(L$59="X","",IF(L$59<>"",L$59,IF(IFERROR(INDEX(醫師週班表!$C$5:$T$44,$CU12,L$57),"")=0,"",IF(MID(IFERROR(INDEX(醫師週班表!$C$5:$T$44,$CU12,L$57),""),2,1)="/",MID(IFERROR(INDEX(醫師週班表!$C$5:$T$44,$CU12,L$57),""),1+L$58*2,1),IF(MID(IFERROR(INDEX(醫師週班表!$C$5:$T$44,$CU12,L$57),""),3,1)="隔",IF(L$58=0,LEFT(IFERROR(INDEX(醫師週班表!$C$5:$T$44,$CU12,L$57),""),1),""),IF(MID(IFERROR(INDEX(醫師週班表!$C$5:$T$44,$CU12,L$57),""),2,1)="(",LEFT(IFERROR(INDEX(醫師週班表!$C$5:$T$44,$CU12,L$57),""),1),IFERROR(INDEX(醫師週班表!$C$5:$T$44,$CU12,L$57),""))))))) | ... CS12: =IF(CS$59="X","",IF(CS$59<>"",CS$59,IF(IFERROR(INDEX(醫師週班表!$C$5:$T$44,$CU12,CS$57),"")=0,"",IF(MID(IFERROR(INDEX(醫師週班表!$C$5:$T$44,$CU12,CS$57),""),2,1)="/",MID(IFERROR(INDEX(醫師週班表!$C$5:$T$44,$CU12,CS$57),""),1+CS$58*2,1),IF(MID(IFERROR(INDEX(醫師週班表!$C$5:$T$44,$CU12,CS$57),""),3,1)="隔",IF(CS$58=0,LEFT(IFERROR(INDEX(醫師週班表!$C$5:$T$44,$CU12,CS$57),""),1),""),IF(MID(IFERROR(INDEX(醫師週班表!$C$5:$T$44,$CU12,CS$57),""),2,1)="(",LEFT(IFERROR(INDEX(醫師週班表!$C$5:$T$44,$CU12,CS$57),""),1),IFERROR(INDEX(醫師週班表!$C$5:$T$44,$CU12,CS$57),""))))))) | CU12: =IFERROR(MATCH($A12,醫師週班表!$A$5:$A$44,0),0)
A13: D008 | B13: 林紫亭 | E13: =IF(E$59="X","",IF(E$59<>"",E$59,IF(IFERROR(INDEX(醫師週班表!$C$5:$T$44,$CU13,E$57),"")=0,"",IF(MID(IFERROR(INDEX(醫師週班表!$C$5:$T$44,$CU13,E$57),""),2,1)="/",MID(IFERROR(INDEX(醫師週班表!$C$5:$T$44,$CU13,E$57),""),1+E$58*2,1),IF(MID(IFERROR(INDEX(醫師週班表!$C$5:$T$44,$CU13,E$57),""),3,1)="隔",IF(E$58=0,LEFT(IFERROR(INDEX(醫師週班表!$C$5:$T$44,$CU13,E$57),""),1),""),IF(MID(IFERROR(INDEX(醫師週班表!$C$5:$T$44,$CU13,E$57),""),2,1)="(",LEFT(IFERROR(INDEX(醫師週班表!$C$5:$T$44,$CU13,E$57),""),1),IFERROR(INDEX(醫師週班表!$C$5:$T$44,$CU13,E$57),""))))))) | F13: =IF(F$59="X","",IF(F$59<>"",F$59,IF(IFERROR(INDEX(醫師週班表!$C$5:$T$44,$CU13,F$57),"")=0,"",IF(MID(IFERROR(INDEX(醫師週班表!$C$5:$T$44,$CU13,F$57),""),2,1)="/",MID(IFERROR(INDEX(醫師週班表!$C$5:$T$44,$CU13,F$57),""),1+F$58*2,1),IF(MID(IFERROR(INDEX(醫師週班表!$C$5:$T$44,$CU13,F$57),""),3,1)="隔",IF(F$58=0,LEFT(IFERROR(INDEX(醫師週班表!$C$5:$T$44,$CU13,F$57),""),1),""),IF(MID(IFERROR(INDEX(醫師週班表!$C$5:$T$44,$CU13,F$57),""),2,1)="(",LEFT(IFERROR(INDEX(醫師週班表!$C$5:$T$44,$CU13,F$57),""),1),IFERROR(INDEX(醫師週班表!$C$5:$T$44,$CU13,F$57),""))))))) | G13: =IF(G$59="X","",IF(G$59<>"",G$59,IF(IFERROR(INDEX(醫師週班表!$C$5:$T$44,$CU13,G$57),"")=0,"",IF(MID(IFERROR(INDEX(醫師週班表!$C$5:$T$44,$CU13,G$57),""),2,1)="/",MID(IFERROR(INDEX(醫師週班表!$C$5:$T$44,$CU13,G$57),""),1+G$58*2,1),IF(MID(IFERROR(INDEX(醫師週班表!$C$5:$T$44,$CU13,G$57),""),3,1)="隔",IF(G$58=0,LEFT(IFERROR(INDEX(醫師週班表!$C$5:$T$44,$CU13,G$57),""),1),""),IF(MID(IFERROR(INDEX(醫師週班表!$C$5:$T$44,$CU13,G$57),""),2,1)="(",LEFT(IFERROR(INDEX(醫師週班表!$C$5:$T$44,$CU13,G$57),""),1),IFERROR(INDEX(醫師週班表!$C$5:$T$44,$CU13,G$57),""))))))) | H13: =IF(H$59="X","",IF(H$59<>"",H$59,IF(IFERROR(INDEX(醫師週班表!$C$5:$T$44,$CU13,H$57),"")=0,"",IF(MID(IFERROR(INDEX(醫師週班表!$C$5:$T$44,$CU13,H$57),""),2,1)="/",MID(IFERROR(INDEX(醫師週班表!$C$5:$T$44,$CU13,H$57),""),1+H$58*2,1),IF(MID(IFERROR(INDEX(醫師週班表!$C$5:$T$44,$CU13,H$57),""),3,1)="隔",IF(H$58=0,LEFT(IFERROR(INDEX(醫師週班表!$C$5:$T$44,$CU13,H$57),""),1),""),IF(MID(IFERROR(INDEX(醫師週班表!$C$5:$T$44,$CU13,H$57),""),2,1)="(",LEFT(IFERROR(INDEX(醫師週班表!$C$5:$T$44,$CU13,H$57),""),1),IFERROR(INDEX(醫師週班表!$C$5:$T$44,$CU13,H$57),""))))))) | I13: =IF(I$59="X","",IF(I$59<>"",I$59,IF(IFERROR(INDEX(醫師週班表!$C$5:$T$44,$CU13,I$57),"")=0,"",IF(MID(IFERROR(INDEX(醫師週班表!$C$5:$T$44,$CU13,I$57),""),2,1)="/",MID(IFERROR(INDEX(醫師週班表!$C$5:$T$44,$CU13,I$57),""),1+I$58*2,1),IF(MID(IFERROR(INDEX(醫師週班表!$C$5:$T$44,$CU13,I$57),""),3,1)="隔",IF(I$58=0,LEFT(IFERROR(INDEX(醫師週班表!$C$5:$T$44,$CU13,I$57),""),1),""),IF(MID(IFERROR(INDEX(醫師週班表!$C$5:$T$44,$CU13,I$57),""),2,1)="(",LEFT(IFERROR(INDEX(醫師週班表!$C$5:$T$44,$CU13,I$57),""),1),IFERROR(INDEX(醫師週班表!$C$5:$T$44,$CU13,I$57),""))))))) | J13: =IF(J$59="X","",IF(J$59<>"",J$59,IF(IFERROR(INDEX(醫師週班表!$C$5:$T$44,$CU13,J$57),"")=0,"",IF(MID(IFERROR(INDEX(醫師週班表!$C$5:$T$44,$CU13,J$57),""),2,1)="/",MID(IFERROR(INDEX(醫師週班表!$C$5:$T$44,$CU13,J$57),""),1+J$58*2,1),IF(MID(IFERROR(INDEX(醫師週班表!$C$5:$T$44,$CU13,J$57),""),3,1)="隔",IF(J$58=0,LEFT(IFERROR(INDEX(醫師週班表!$C$5:$T$44,$CU13,J$57),""),1),""),IF(MID(IFERROR(INDEX(醫師週班表!$C$5:$T$44,$CU13,J$57),""),2,1)="(",LEFT(IFERROR(INDEX(醫師週班表!$C$5:$T$44,$CU13,J$57),""),1),IFERROR(INDEX(醫師週班表!$C$5:$T$44,$CU13,J$57),""))))))) | K13: =IF(K$59="X","",IF(K$59<>"",K$59,IF(IFERROR(INDEX(醫師週班表!$C$5:$T$44,$CU13,K$57),"")=0,"",IF(MID(IFERROR(INDEX(醫師週班表!$C$5:$T$44,$CU13,K$57),""),2,1)="/",MID(IFERROR(INDEX(醫師週班表!$C$5:$T$44,$CU13,K$57),""),1+K$58*2,1),IF(MID(IFERROR(INDEX(醫師週班表!$C$5:$T$44,$CU13,K$57),""),3,1)="隔",IF(K$58=0,LEFT(IFERROR(INDEX(醫師週班表!$C$5:$T$44,$CU13,K$57),""),1),""),IF(MID(IFERROR(INDEX(醫師週班表!$C$5:$T$44,$CU13,K$57),""),2,1)="(",LEFT(IFERROR(INDEX(醫師週班表!$C$5:$T$44,$CU13,K$57),""),1),IFERROR(INDEX(醫師週班表!$C$5:$T$44,$CU13,K$57),""))))))) | L13: =IF(L$59="X","",IF(L$59<>"",L$59,IF(IFERROR(INDEX(醫師週班表!$C$5:$T$44,$CU13,L$57),"")=0,"",IF(MID(IFERROR(INDEX(醫師週班表!$C$5:$T$44,$CU13,L$57),""),2,1)="/",MID(IFERROR(INDEX(醫師週班表!$C$5:$T$44,$CU13,L$57),""),1+L$58*2,1),IF(MID(IFERROR(INDEX(醫師週班表!$C$5:$T$44,$CU13,L$57),""),3,1)="隔",IF(L$58=0,LEFT(IFERROR(INDEX(醫師週班表!$C$5:$T$44,$CU13,L$57),""),1),""),IF(MID(IFERROR(INDEX(醫師週班表!$C$5:$T$44,$CU13,L$57),""),2,1)="(",LEFT(IFERROR(INDEX(醫師週班表!$C$5:$T$44,$CU13,L$57),""),1),IFERROR(INDEX(醫師週班表!$C$5:$T$44,$CU13,L$57),""))))))) | ... CS13: =IF(CS$59="X","",IF(CS$59<>"",CS$59,IF(IFERROR(INDEX(醫師週班表!$C$5:$T$44,$CU13,CS$57),"")=0,"",IF(MID(IFERROR(INDEX(醫師週班表!$C$5:$T$44,$CU13,CS$57),""),2,1)="/",MID(IFERROR(INDEX(醫師週班表!$C$5:$T$44,$CU13,CS$57),""),1+CS$58*2,1),IF(MID(IFERROR(INDEX(醫師週班表!$C$5:$T$44,$CU13,CS$57),""),3,1)="隔",IF(CS$58=0,LEFT(IFERROR(INDEX(醫師週班表!$C$5:$T$44,$CU13,CS$57),""),1),""),IF(MID(IFERROR(INDEX(醫師週班表!$C$5:$T$44,$CU13,CS$57),""),2,1)="(",LEFT(IFERROR(INDEX(醫師週班表!$C$5:$T$44,$CU13,CS$57),""),1),IFERROR(INDEX(醫師週班表!$C$5:$T$44,$CU13,CS$57),""))))))) | CU13: =IFERROR(MATCH($A13,醫師週班表!$A$5:$A$44,0),0)
A14: D009 | B14: 陳昺元 | C14: 美學植牙專科 | D14: 晶匯院長 | E14: =IF(E$59="X","",IF(E$59<>"",E$59,IF(IFERROR(INDEX(醫師週班表!$C$5:$T$44,$CU14,E$57),"")=0,"",IF(MID(IFERROR(INDEX(醫師週班表!$C$5:$T$44,$CU14,E$57),""),2,1)="/",MID(IFERROR(INDEX(醫師週班表!$C$5:$T$44,$CU14,E$57),""),1+E$58*2,1),IF(MID(IFERROR(INDEX(醫師週班表!$C$5:$T$44,$CU14,E$57),""),3,1)="隔",IF(E$58=0,LEFT(IFERROR(INDEX(醫師週班表!$C$5:$T$44,$CU14,E$57),""),1),""),IF(MID(IFERROR(INDEX(醫師週班表!$C$5:$T$44,$CU14,E$57),""),2,1)="(",LEFT(IFERROR(INDEX(醫師週班表!$C$5:$T$44,$CU14,E$57),""),1),IFERROR(INDEX(醫師週班表!$C$5:$T$44,$CU14,E$57),""))))))) | F14: =IF(F$59="X","",IF(F$59<>"",F$59,IF(IFERROR(INDEX(醫師週班表!$C$5:$T$44,$CU14,F$57),"")=0,"",IF(MID(IFERROR(INDEX(醫師週班表!$C$5:$T$44,$CU14,F$57),""),2,1)="/",MID(IFERROR(INDEX(醫師週班表!$C$5:$T$44,$CU14,F$57),""),1+F$58*2,1),IF(MID(IFERROR(INDEX(醫師週班表!$C$5:$T$44,$CU14,F$57),""),3,1)="隔",IF(F$58=0,LEFT(IFERROR(INDEX(醫師週班表!$C$5:$T$44,$CU14,F$57),""),1),""),IF(MID(IFERROR(INDEX(醫師週班表!$C$5:$T$44,$CU14,F$57),""),2,1)="(",LEFT(IFERROR(INDEX(醫師週班表!$C$5:$T$44,$CU14,F$57),""),1),IFERROR(INDEX(醫師週班表!$C$5:$T$44,$CU14,F$57),""))))))) | G14: =IF(G$59="X","",IF(G$59<>"",G$59,IF(IFERROR(INDEX(醫師週班表!$C$5:$T$44,$CU14,G$57),"")=0,"",IF(MID(IFERROR(INDEX(醫師週班表!$C$5:$T$44,$CU14,G$57),""),2,1)="/",MID(IFERROR(INDEX(醫師週班表!$C$5:$T$44,$CU14,G$57),""),1+G$58*2,1),IF(MID(IFERROR(INDEX(醫師週班表!$C$5:$T$44,$CU14,G$57),""),3,1)="隔",IF(G$58=0,LEFT(IFERROR(INDEX(醫師週班表!$C$5:$T$44,$CU14,G$57),""),1),""),IF(MID(IFERROR(INDEX(醫師週班表!$C$5:$T$44,$CU14,G$57),""),2,1)="(",LEFT(IFERROR(INDEX(醫師週班表!$C$5:$T$44,$CU14,G$57),""),1),IFERROR(INDEX(醫師週班表!$C$5:$T$44,$CU14,G$57),""))))))) | H14: =IF(H$59="X","",IF(H$59<>"",H$59,IF(IFERROR(INDEX(醫師週班表!$C$5:$T$44,$CU14,H$57),"")=0,"",IF(MID(IFERROR(INDEX(醫師週班表!$C$5:$T$44,$CU14,H$57),""),2,1)="/",MID(IFERROR(INDEX(醫師週班表!$C$5:$T$44,$CU14,H$57),""),1+H$58*2,1),IF(MID(IFERROR(INDEX(醫師週班表!$C$5:$T$44,$CU14,H$57),""),3,1)="隔",IF(H$58=0,LEFT(IFERROR(INDEX(醫師週班表!$C$5:$T$44,$CU14,H$57),""),1),""),IF(MID(IFERROR(INDEX(醫師週班表!$C$5:$T$44,$CU14,H$57),""),2,1)="(",LEFT(IFERROR(INDEX(醫師週班表!$C$5:$T$44,$CU14,H$57),""),1),IFERROR(INDEX(醫師週班表!$C$5:$T$44,$CU14,H$57),""))))))) | I14: =IF(I$59="X","",IF(I$59<>"",I$59,IF(IFERROR(INDEX(醫師週班表!$C$5:$T$44,$CU14,I$57),"")=0,"",IF(MID(IFERROR(INDEX(醫師週班表!$C$5:$T$44,$CU14,I$57),""),2,1)="/",MID(IFERROR(INDEX(醫師週班表!$C$5:$T$44,$CU14,I$57),""),1+I$58*2,1),IF(MID(IFERROR(INDEX(醫師週班表!$C$5:$T$44,$CU14,I$57),""),3,1)="隔",IF(I$58=0,LEFT(IFERROR(INDEX(醫師週班表!$C$5:$T$44,$CU14,I$57),""),1),""),IF(MID(IFERROR(INDEX(醫師週班表!$C$5:$T$44,$CU14,I$57),""),2,1)="(",LEFT(IFERROR(INDEX(醫師週班表!$C$5:$T$44,$CU14,I$57),""),1),IFERROR(INDEX(醫師週班表!$C$5:$T$44,$CU14,I$57),""))))))) | J14: =IF(J$59="X","",IF(J$59<>"",J$59,IF(IFERROR(INDEX(醫師週班表!$C$5:$T$44,$CU14,J$57),"")=0,"",IF(MID(IFERROR(INDEX(醫師週班表!$C$5:$T$44,$CU14,J$57),""),2,1)="/",MID(IFERROR(INDEX(醫師週班表!$C$5:$T$44,$CU14,J$57),""),1+J$58*2,1),IF(MID(IFERROR(INDEX(醫師週班表!$C$5:$T$44,$CU14,J$57),""),3,1)="隔",IF(J$58=0,LEFT(IFERROR(INDEX(醫師週班表!$C$5:$T$44,$CU14,J$57),""),1),""),IF(MID(IFERROR(INDEX(醫師週班表!$C$5:$T$44,$CU14,J$57),""),2,1)="(",LEFT(IFERROR(INDEX(醫師週班表!$C$5:$T$44,$CU14,J$57),""),1),IFERROR(INDEX(醫師週班表!$C$5:$T$44,$CU14,J$57),""))))))) | K14: =IF(K$59="X","",IF(K$59<>"",K$59,IF(IFERROR(INDEX(醫師週班表!$C$5:$T$44,$CU14,K$57),"")=0,"",IF(MID(IFERROR(INDEX(醫師週班表!$C$5:$T$44,$CU14,K$57),""),2,1)="/",MID(IFERROR(INDEX(醫師週班表!$C$5:$T$44,$CU14,K$57),""),1+K$58*2,1),IF(MID(IFERROR(INDEX(醫師週班表!$C$5:$T$44,$CU14,K$57),""),3,1)="隔",IF(K$58=0,LEFT(IFERROR(INDEX(醫師週班表!$C$5:$T$44,$CU14,K$57),""),1),""),IF(MID(IFERROR(INDEX(醫師週班表!$C$5:$T$44,$CU14,K$57),""),2,1)="(",LEFT(IFERROR(INDEX(醫師週班表!$C$5:$T$44,$CU14,K$57),""),1),IFERROR(INDEX(醫師週班表!$C$5:$T$44,$CU14,K$57),""))))))) | L14: =IF(L$59="X","",IF(L$59<>"",L$59,IF(IFERROR(INDEX(醫師週班表!$C$5:$T$44,$CU14,L$57),"")=0,"",IF(MID(IFERROR(INDEX(醫師週班表!$C$5:$T$44,$CU14,L$57),""),2,1)="/",MID(IFERROR(INDEX(醫師週班表!$C$5:$T$44,$CU14,L$57),""),1+L$58*2,1),IF(MID(IFERROR(INDEX(醫師週班表!$C$5:$T$44,$CU14,L$57),""),3,1)="隔",IF(L$58=0,LEFT(IFERROR(INDEX(醫師週班表!$C$5:$T$44,$CU14,L$57),""),1),""),IF(MID(IFERROR(INDEX(醫師週班表!$C$5:$T$44,$CU14,L$57),""),2,1)="(",LEFT(IFERROR(INDEX(醫師週班表!$C$5:$T$44,$CU14,L$57),""),1),IFERROR(INDEX(醫師週班表!$C$5:$T$44,$CU14,L$57),""))))))) | ... CS14: =IF(CS$59="X","",IF(CS$59<>"",CS$59,IF(IFERROR(INDEX(醫師週班表!$C$5:$T$44,$CU14,CS$57),"")=0,"",IF(MID(IFERROR(INDEX(醫師週班表!$C$5:$T$44,$CU14,CS$57),""),2,1)="/",MID(IFERROR(INDEX(醫師週班表!$C$5:$T$44,$CU14,CS$57),""),1+CS$58*2,1),IF(MID(IFERROR(INDEX(醫師週班表!$C$5:$T$44,$CU14,CS$57),""),3,1)="隔",IF(CS$58=0,LEFT(IFERROR(INDEX(醫師週班表!$C$5:$T$44,$CU14,CS$57),""),1),""),IF(MID(IFERROR(INDEX(醫師週班表!$C$5:$T$44,$CU14,CS$57),""),2,1)="(",LEFT(IFERROR(INDEX(醫師週班表!$C$5:$T$44,$CU14,CS$57),""),1),IFERROR(INDEX(醫師週班表!$C$5:$T$44,$CU14,CS$57),""))))))) | CU14: =IFERROR(MATCH($A14,醫師週班表!$A$5:$A$44,0),0)
A15: D010 | B15: 蔡季軒 | E15: =IF(E$59="X","",IF(E$59<>"",E$59,IF(IFERROR(INDEX(醫師週班表!$C$5:$T$44,$CU15,E$57),"")=0,"",IF(MID(IFERROR(INDEX(醫師週班表!$C$5:$T$44,$CU15,E$57),""),2,1)="/",MID(IFERROR(INDEX(醫師週班表!$C$5:$T$44,$CU15,E$57),""),1+E$58*2,1),IF(MID(IFERROR(INDEX(醫師週班表!$C$5:$T$44,$CU15,E$57),""),3,1)="隔",IF(E$58=0,LEFT(IFERROR(INDEX(醫師週班表!$C$5:$T$44,$CU15,E$57),""),1),""),IF(MID(IFERROR(INDEX(醫師週班表!$C$5:$T$44,$CU15,E$57),""),2,1)="(",LEFT(IFERROR(INDEX(醫師週班表!$C$5:$T$44,$CU15,E$57),""),1),IFERROR(INDEX(醫師週班表!$C$5:$T$44,$CU15,E$57),""))))))) | F15: =IF(F$59="X","",IF(F$59<>"",F$59,IF(IFERROR(INDEX(醫師週班表!$C$5:$T$44,$CU15,F$57),"")=0,"",IF(MID(IFERROR(INDEX(醫師週班表!$C$5:$T$44,$CU15,F$57),""),2,1)="/",MID(IFERROR(INDEX(醫師週班表!$C$5:$T$44,$CU15,F$57),""),1+F$58*2,1),IF(MID(IFERROR(INDEX(醫師週班表!$C$5:$T$44,$CU15,F$57),""),3,1)="隔",IF(F$58=0,LEFT(IFERROR(INDEX(醫師週班表!$C$5:$T$44,$CU15,F$57),""),1),""),IF(MID(IFERROR(INDEX(醫師週班表!$C$5:$T$44,$CU15,F$57),""),2,1)="(",LEFT(IFERROR(INDEX(醫師週班表!$C$5:$T$44,$CU15,F$57),""),1),IFERROR(INDEX(醫師週班表!$C$5:$T$44,$CU15,F$57),""))))))) | G15: =IF(G$59="X","",IF(G$59<>"",G$59,IF(IFERROR(INDEX(醫師週班表!$C$5:$T$44,$CU15,G$57),"")=0,"",IF(MID(IFERROR(INDEX(醫師週班表!$C$5:$T$44,$CU15,G$57),""),2,1)="/",MID(IFERROR(INDEX(醫師週班表!$C$5:$T$44,$CU15,G$57),""),1+G$58*2,1),IF(MID(IFERROR(INDEX(醫師週班表!$C$5:$T$44,$CU15,G$57),""),3,1)="隔",IF(G$58=0,LEFT(IFERROR(INDEX(醫師週班表!$C$5:$T$44,$CU15,G$57),""),1),""),IF(MID(IFERROR(INDEX(醫師週班表!$C$5:$T$44,$CU15,G$57),""),2,1)="(",LEFT(IFERROR(INDEX(醫師週班表!$C$5:$T$44,$CU15,G$57),""),1),IFERROR(INDEX(醫師週班表!$C$5:$T$44,$CU15,G$57),""))))))) | H15: =IF(H$59="X","",IF(H$59<>"",H$59,IF(IFERROR(INDEX(醫師週班表!$C$5:$T$44,$CU15,H$57),"")=0,"",IF(MID(IFERROR(INDEX(醫師週班表!$C$5:$T$44,$CU15,H$57),""),2,1)="/",MID(IFERROR(INDEX(醫師週班表!$C$5:$T$44,$CU15,H$57),""),1+H$58*2,1),IF(MID(IFERROR(INDEX(醫師週班表!$C$5:$T$44,$CU15,H$57),""),3,1)="隔",IF(H$58=0,LEFT(IFERROR(INDEX(醫師週班表!$C$5:$T$44,$CU15,H$57),""),1),""),IF(MID(IFERROR(INDEX(醫師週班表!$C$5:$T$44,$CU15,H$57),""),2,1)="(",LEFT(IFERROR(INDEX(醫師週班表!$C$5:$T$44,$CU15,H$57),""),1),IFERROR(INDEX(醫師週班表!$C$5:$T$44,$CU15,H$57),""))))))) | I15: =IF(I$59="X","",IF(I$59<>"",I$59,IF(IFERROR(INDEX(醫師週班表!$C$5:$T$44,$CU15,I$57),"")=0,"",IF(MID(IFERROR(INDEX(醫師週班表!$C$5:$T$44,$CU15,I$57),""),2,1)="/",MID(IFERROR(INDEX(醫師週班表!$C$5:$T$44,$CU15,I$57),""),1+I$58*2,1),IF(MID(IFERROR(INDEX(醫師週班表!$C$5:$T$44,$CU15,I$57),""),3,1)="隔",IF(I$58=0,LEFT(IFERROR(INDEX(醫師週班表!$C$5:$T$44,$CU15,I$57),""),1),""),IF(MID(IFERROR(INDEX(醫師週班表!$C$5:$T$44,$CU15,I$57),""),2,1)="(",LEFT(IFERROR(INDEX(醫師週班表!$C$5:$T$44,$CU15,I$57),""),1),IFERROR(INDEX(醫師週班表!$C$5:$T$44,$CU15,I$57),""))))))) | J15: =IF(J$59="X","",IF(J$59<>"",J$59,IF(IFERROR(INDEX(醫師週班表!$C$5:$T$44,$CU15,J$57),"")=0,"",IF(MID(IFERROR(INDEX(醫師週班表!$C$5:$T$44,$CU15,J$57),""),2,1)="/",MID(IFERROR(INDEX(醫師週班表!$C$5:$T$44,$CU15,J$57),""),1+J$58*2,1),IF(MID(IFERROR(INDEX(醫師週班表!$C$5:$T$44,$CU15,J$57),""),3,1)="隔",IF(J$58=0,LEFT(IFERROR(INDEX(醫師週班表!$C$5:$T$44,$CU15,J$57),""),1),""),IF(MID(IFERROR(INDEX(醫師週班表!$C$5:$T$44,$CU15,J$57),""),2,1)="(",LEFT(IFERROR(INDEX(醫師週班表!$C$5:$T$44,$CU15,J$57),""),1),IFERROR(INDEX(醫師週班表!$C$5:$T$44,$CU15,J$57),""))))))) | K15: =IF(K$59="X","",IF(K$59<>"",K$59,IF(IFERROR(INDEX(醫師週班表!$C$5:$T$44,$CU15,K$57),"")=0,"",IF(MID(IFERROR(INDEX(醫師週班表!$C$5:$T$44,$CU15,K$57),""),2,1)="/",MID(IFERROR(INDEX(醫師週班表!$C$5:$T$44,$CU15,K$57),""),1+K$58*2,1),IF(MID(IFERROR(INDEX(醫師週班表!$C$5:$T$44,$CU15,K$57),""),3,1)="隔",IF(K$58=0,LEFT(IFERROR(INDEX(醫師週班表!$C$5:$T$44,$CU15,K$57),""),1),""),IF(MID(IFERROR(INDEX(醫師週班表!$C$5:$T$44,$CU15,K$57),""),2,1)="(",LEFT(IFERROR(INDEX(醫師週班表!$C$5:$T$44,$CU15,K$57),""),1),IFERROR(INDEX(醫師週班表!$C$5:$T$44,$CU15,K$57),""))))))) | L15: =IF(L$59="X","",IF(L$59<>"",L$59,IF(IFERROR(INDEX(醫師週班表!$C$5:$T$44,$CU15,L$57),"")=0,"",IF(MID(IFERROR(INDEX(醫師週班表!$C$5:$T$44,$CU15,L$57),""),2,1)="/",MID(IFERROR(INDEX(醫師週班表!$C$5:$T$44,$CU15,L$57),""),1+L$58*2,1),IF(MID(IFERROR(INDEX(醫師週班表!$C$5:$T$44,$CU15,L$57),""),3,1)="隔",IF(L$58=0,LEFT(IFERROR(INDEX(醫師週班表!$C$5:$T$44,$CU15,L$57),""),1),""),IF(MID(IFERROR(INDEX(醫師週班表!$C$5:$T$44,$CU15,L$57),""),2,1)="(",LEFT(IFERROR(INDEX(醫師週班表!$C$5:$T$44,$CU15,L$57),""),1),IFERROR(INDEX(醫師週班表!$C$5:$T$44,$CU15,L$57),""))))))) | ... CS15: =IF(CS$59="X","",IF(CS$59<>"",CS$59,IF(IFERROR(INDEX(醫師週班表!$C$5:$T$44,$CU15,CS$57),"")=0,"",IF(MID(IFERROR(INDEX(醫師週班表!$C$5:$T$44,$CU15,CS$57),""),2,1)="/",MID(IFERROR(INDEX(醫師週班表!$C$5:$T$44,$CU15,CS$57),""),1+CS$58*2,1),IF(MID(IFERROR(INDEX(醫師週班表!$C$5:$T$44,$CU15,CS$57),""),3,1)="隔",IF(CS$58=0,LEFT(IFERROR(INDEX(醫師週班表!$C$5:$T$44,$CU15,CS$57),""),1),""),IF(MID(IFERROR(INDEX(醫師週班表!$C$5:$T$44,$CU15,CS$57),""),2,1)="(",LEFT(IFERROR(INDEX(醫師週班表!$C$5:$T$44,$CU15,CS$57),""),1),IFERROR(INDEX(醫師週班表!$C$5:$T$44,$CU15,CS$57),""))))))) | CU15: =IFERROR(MATCH($A15,醫師週班表!$A$5:$A$44,0),0)
